ERROR 2024-02-21 20:35:47,868 log 22904 2212 Internal Server Error: /connect-with-ftp
Traceback (most recent call last):
  File "e:\NAL-USDA\NAL_LIBRARY_SYSTEM\env\Lib\site-packages\django\core\handlers\exception.py", line 55, in inner
    response = get_response(request)
               ^^^^^^^^^^^^^^^^^^^^^
  File "e:\NAL-USDA\NAL_LIBRARY_SYSTEM\env\Lib\site-packages\django\core\handlers\base.py", line 220, in _get_response
    response = response.render()
               ^^^^^^^^^^^^^^^^^
  File "e:\NAL-USDA\NAL_LIBRARY_SYSTEM\env\Lib\site-packages\django\template\response.py", line 111, in render
    self.content = self.rendered_content
                   ^^^^^^^^^^^^^^^^^^^^^
  File "e:\NAL-USDA\NAL_LIBRARY_SYSTEM\env\Lib\site-packages\rest_framework\response.py", line 55, in rendered_content
    assert renderer, ".accepted_renderer not set on Response"
AssertionError: .accepted_renderer not set on Response
ERROR 2024-02-21 20:35:47,877 basehttp 22904 2212 "GET /connect-with-ftp HTTP/1.1" 500 92523
ERROR 2024-02-21 20:36:38,902 log 22904 2212 Internal Server Error: /connect-with-ftp
Traceback (most recent call last):
  File "e:\NAL-USDA\NAL_LIBRARY_SYSTEM\env\Lib\site-packages\django\core\handlers\exception.py", line 55, in inner
    response = get_response(request)
               ^^^^^^^^^^^^^^^^^^^^^
  File "e:\NAL-USDA\NAL_LIBRARY_SYSTEM\env\Lib\site-packages\django\core\handlers\base.py", line 220, in _get_response
    response = response.render()
               ^^^^^^^^^^^^^^^^^
  File "e:\NAL-USDA\NAL_LIBRARY_SYSTEM\env\Lib\site-packages\django\template\response.py", line 111, in render
    self.content = self.rendered_content
                   ^^^^^^^^^^^^^^^^^^^^^
  File "e:\NAL-USDA\NAL_LIBRARY_SYSTEM\env\Lib\site-packages\rest_framework\response.py", line 55, in rendered_content
    assert renderer, ".accepted_renderer not set on Response"
AssertionError: .accepted_renderer not set on Response
ERROR 2024-02-21 20:36:38,906 basehttp 22904 2212 "GET /connect-with-ftp HTTP/1.1" 500 92523
ERROR 2024-02-21 20:49:41,823 log 19912 25376 Internal Server Error: /connect-with-ftp
Traceback (most recent call last):
  File "e:\NAL-USDA\NAL_LIBRARY_SYSTEM\env\Lib\site-packages\django\core\handlers\exception.py", line 55, in inner
    response = get_response(request)
               ^^^^^^^^^^^^^^^^^^^^^
  File "e:\NAL-USDA\NAL_LIBRARY_SYSTEM\env\Lib\site-packages\django\core\handlers\base.py", line 220, in _get_response
    response = response.render()
               ^^^^^^^^^^^^^^^^^
  File "e:\NAL-USDA\NAL_LIBRARY_SYSTEM\env\Lib\site-packages\django\template\response.py", line 111, in render
    self.content = self.rendered_content
                   ^^^^^^^^^^^^^^^^^^^^^
  File "e:\NAL-USDA\NAL_LIBRARY_SYSTEM\env\Lib\site-packages\rest_framework\response.py", line 55, in rendered_content
    assert renderer, ".accepted_renderer not set on Response"
AssertionError: .accepted_renderer not set on Response
ERROR 2024-02-21 20:49:41,827 basehttp 19912 25376 "GET /connect-with-ftp HTTP/1.1" 500 92523
ERROR 2024-02-22 19:36:03,347 log 33092 32144 Internal Server Error: /connect-with-ftp
Traceback (most recent call last):
  File "e:\NAL-USDA\NAL_LIBRARY_SYSTEM\env\Lib\site-packages\django\core\handlers\exception.py", line 55, in inner
    response = get_response(request)
               ^^^^^^^^^^^^^^^^^^^^^
  File "e:\NAL-USDA\NAL_LIBRARY_SYSTEM\env\Lib\site-packages\django\core\handlers\base.py", line 220, in _get_response
    response = response.render()
               ^^^^^^^^^^^^^^^^^
  File "e:\NAL-USDA\NAL_LIBRARY_SYSTEM\env\Lib\site-packages\django\template\response.py", line 111, in render
    self.content = self.rendered_content
                   ^^^^^^^^^^^^^^^^^^^^^
  File "e:\NAL-USDA\NAL_LIBRARY_SYSTEM\env\Lib\site-packages\rest_framework\response.py", line 55, in rendered_content
    assert renderer, ".accepted_renderer not set on Response"
AssertionError: .accepted_renderer not set on Response
ERROR 2024-02-22 19:36:03,354 basehttp 33092 32144 "GET /connect-with-ftp HTTP/1.1" 500 92523
ERROR 2024-02-22 20:20:51,524 log 15816 31188 Internal Server Error: /connect-with-ftp
Traceback (most recent call last):
  File "e:\NAL-USDA\NAL_LIBRARY_SYSTEM\env\Lib\site-packages\django\core\handlers\exception.py", line 55, in inner
    response = get_response(request)
               ^^^^^^^^^^^^^^^^^^^^^
  File "e:\NAL-USDA\NAL_LIBRARY_SYSTEM\env\Lib\site-packages\django\core\handlers\base.py", line 220, in _get_response
    response = response.render()
               ^^^^^^^^^^^^^^^^^
  File "e:\NAL-USDA\NAL_LIBRARY_SYSTEM\env\Lib\site-packages\django\template\response.py", line 111, in render
    self.content = self.rendered_content
                   ^^^^^^^^^^^^^^^^^^^^^
  File "e:\NAL-USDA\NAL_LIBRARY_SYSTEM\env\Lib\site-packages\rest_framework\response.py", line 55, in rendered_content
    assert renderer, ".accepted_renderer not set on Response"
AssertionError: .accepted_renderer not set on Response
ERROR 2024-02-22 20:20:51,530 basehttp 15816 31188 "GET /connect-with-ftp HTTP/1.1" 500 92508
ERROR 2024-02-22 20:22:40,990 log 24808 28996 Internal Server Error: /connect-with-ftp
Traceback (most recent call last):
  File "e:\NAL-USDA\NAL_LIBRARY_SYSTEM\env\Lib\site-packages\django\core\handlers\exception.py", line 55, in inner
    response = get_response(request)
               ^^^^^^^^^^^^^^^^^^^^^
  File "e:\NAL-USDA\NAL_LIBRARY_SYSTEM\env\Lib\site-packages\django\core\handlers\base.py", line 220, in _get_response
    response = response.render()
               ^^^^^^^^^^^^^^^^^
  File "e:\NAL-USDA\NAL_LIBRARY_SYSTEM\env\Lib\site-packages\django\template\response.py", line 111, in render
    self.content = self.rendered_content
                   ^^^^^^^^^^^^^^^^^^^^^
  File "e:\NAL-USDA\NAL_LIBRARY_SYSTEM\env\Lib\site-packages\rest_framework\response.py", line 55, in rendered_content
    assert renderer, ".accepted_renderer not set on Response"
AssertionError: .accepted_renderer not set on Response
ERROR 2024-02-22 20:22:40,995 basehttp 24808 28996 "GET /connect-with-ftp HTTP/1.1" 500 92523
ERROR 2024-02-22 20:22:43,042 log 24808 984 Internal Server Error: /connect-with-ftp
Traceback (most recent call last):
  File "e:\NAL-USDA\NAL_LIBRARY_SYSTEM\env\Lib\site-packages\django\core\handlers\exception.py", line 55, in inner
    response = get_response(request)
               ^^^^^^^^^^^^^^^^^^^^^
  File "e:\NAL-USDA\NAL_LIBRARY_SYSTEM\env\Lib\site-packages\django\core\handlers\base.py", line 220, in _get_response
    response = response.render()
               ^^^^^^^^^^^^^^^^^
  File "e:\NAL-USDA\NAL_LIBRARY_SYSTEM\env\Lib\site-packages\django\template\response.py", line 111, in render
    self.content = self.rendered_content
                   ^^^^^^^^^^^^^^^^^^^^^
  File "e:\NAL-USDA\NAL_LIBRARY_SYSTEM\env\Lib\site-packages\rest_framework\response.py", line 55, in rendered_content
    assert renderer, ".accepted_renderer not set on Response"
AssertionError: .accepted_renderer not set on Response
ERROR 2024-02-22 20:22:43,043 basehttp 24808 984 "GET /connect-with-ftp HTTP/1.1" 500 92523
ERROR 2024-02-22 20:29:26,830 log 26656 5724 Internal Server Error: /connect-with-ftp
Traceback (most recent call last):
  File "e:\NAL-USDA\NAL_LIBRARY_SYSTEM\env\Lib\site-packages\django\core\handlers\exception.py", line 55, in inner
    response = get_response(request)
               ^^^^^^^^^^^^^^^^^^^^^
  File "e:\NAL-USDA\NAL_LIBRARY_SYSTEM\env\Lib\site-packages\django\core\handlers\base.py", line 220, in _get_response
    response = response.render()
               ^^^^^^^^^^^^^^^^^
  File "e:\NAL-USDA\NAL_LIBRARY_SYSTEM\env\Lib\site-packages\django\template\response.py", line 111, in render
    self.content = self.rendered_content
                   ^^^^^^^^^^^^^^^^^^^^^
  File "e:\NAL-USDA\NAL_LIBRARY_SYSTEM\env\Lib\site-packages\rest_framework\response.py", line 55, in rendered_content
    assert renderer, ".accepted_renderer not set on Response"
AssertionError: .accepted_renderer not set on Response
ERROR 2024-02-22 20:29:26,835 basehttp 26656 5724 "GET /connect-with-ftp HTTP/1.1" 500 92523
ERROR 2024-02-22 20:29:28,809 log 26656 24480 Internal Server Error: /connect-with-ftp
Traceback (most recent call last):
  File "e:\NAL-USDA\NAL_LIBRARY_SYSTEM\env\Lib\site-packages\django\core\handlers\exception.py", line 55, in inner
    response = get_response(request)
               ^^^^^^^^^^^^^^^^^^^^^
  File "e:\NAL-USDA\NAL_LIBRARY_SYSTEM\env\Lib\site-packages\django\core\handlers\base.py", line 220, in _get_response
    response = response.render()
               ^^^^^^^^^^^^^^^^^
  File "e:\NAL-USDA\NAL_LIBRARY_SYSTEM\env\Lib\site-packages\django\template\response.py", line 111, in render
    self.content = self.rendered_content
                   ^^^^^^^^^^^^^^^^^^^^^
  File "e:\NAL-USDA\NAL_LIBRARY_SYSTEM\env\Lib\site-packages\rest_framework\response.py", line 55, in rendered_content
    assert renderer, ".accepted_renderer not set on Response"
AssertionError: .accepted_renderer not set on Response
ERROR 2024-02-22 20:29:28,811 basehttp 26656 24480 "GET /connect-with-ftp HTTP/1.1" 500 92523
ERROR 2024-02-22 20:36:23,523 log 25192 3052 Internal Server Error: /connect-with-ftp
Traceback (most recent call last):
  File "e:\NAL-USDA\NAL_LIBRARY_SYSTEM\env\Lib\site-packages\django\core\handlers\exception.py", line 55, in inner
    response = get_response(request)
               ^^^^^^^^^^^^^^^^^^^^^
  File "e:\NAL-USDA\NAL_LIBRARY_SYSTEM\env\Lib\site-packages\django\core\handlers\base.py", line 220, in _get_response
    response = response.render()
               ^^^^^^^^^^^^^^^^^
  File "e:\NAL-USDA\NAL_LIBRARY_SYSTEM\env\Lib\site-packages\django\template\response.py", line 111, in render
    self.content = self.rendered_content
                   ^^^^^^^^^^^^^^^^^^^^^
  File "e:\NAL-USDA\NAL_LIBRARY_SYSTEM\env\Lib\site-packages\rest_framework\response.py", line 55, in rendered_content
    assert renderer, ".accepted_renderer not set on Response"
AssertionError: .accepted_renderer not set on Response
ERROR 2024-02-22 20:36:23,529 basehttp 25192 3052 "GET /connect-with-ftp HTTP/1.1" 500 92398
ERROR 2024-02-22 20:41:30,818 log 29064 3428 Internal Server Error: /providers-ftp/
Traceback (most recent call last):
  File "e:\NAL-USDA\NAL_LIBRARY_SYSTEM\env\Lib\site-packages\django\db\backends\utils.py", line 89, in _execute
    return self.cursor.execute(sql, params)
           ^^^^^^^^^^^^^^^^^^^^^^^^^^^^^^^^
  File "e:\NAL-USDA\NAL_LIBRARY_SYSTEM\env\Lib\site-packages\django\db\backends\mysql\base.py", line 75, in execute
    return self.cursor.execute(query, args)
           ^^^^^^^^^^^^^^^^^^^^^^^^^^^^^^^^
  File "e:\NAL-USDA\NAL_LIBRARY_SYSTEM\env\Lib\site-packages\MySQLdb\cursors.py", line 179, in execute
    res = self._query(mogrified_query)
          ^^^^^^^^^^^^^^^^^^^^^^^^^^^^
  File "e:\NAL-USDA\NAL_LIBRARY_SYSTEM\env\Lib\site-packages\MySQLdb\cursors.py", line 331, in _query
    self._do_get_result(db)
  File "e:\NAL-USDA\NAL_LIBRARY_SYSTEM\env\Lib\site-packages\MySQLdb\cursors.py", line 136, in _do_get_result
    self._result = result = self._get_result()
                            ^^^^^^^^^^^^^^^^^^
  File "e:\NAL-USDA\NAL_LIBRARY_SYSTEM\env\Lib\site-packages\MySQLdb\cursors.py", line 363, in _get_result
    return self._get_db().store_result()
           ^^^^^^^^^^^^^^^^^^^^^^^^^^^^^
MySQLdb.DataError: (1406, "Data too long for column 'password' at row 1")

The above exception was the direct cause of the following exception:

Traceback (most recent call last):
  File "e:\NAL-USDA\NAL_LIBRARY_SYSTEM\env\Lib\site-packages\django\core\handlers\exception.py", line 55, in inner
    response = get_response(request)
               ^^^^^^^^^^^^^^^^^^^^^
  File "e:\NAL-USDA\NAL_LIBRARY_SYSTEM\env\Lib\site-packages\django\core\handlers\base.py", line 197, in _get_response
    response = wrapped_callback(request, *callback_args, **callback_kwargs)
               ^^^^^^^^^^^^^^^^^^^^^^^^^^^^^^^^^^^^^^^^^^^^^^^^^^^^^^^^^^^^
  File "e:\NAL-USDA\NAL_LIBRARY_SYSTEM\env\Lib\site-packages\django\views\decorators\csrf.py", line 56, in wrapper_view
    return view_func(*args, **kwargs)
           ^^^^^^^^^^^^^^^^^^^^^^^^^^
  File "e:\NAL-USDA\NAL_LIBRARY_SYSTEM\env\Lib\site-packages\rest_framework\viewsets.py", line 125, in view
    return self.dispatch(request, *args, **kwargs)
           ^^^^^^^^^^^^^^^^^^^^^^^^^^^^^^^^^^^^^^^
  File "e:\NAL-USDA\NAL_LIBRARY_SYSTEM\env\Lib\site-packages\rest_framework\views.py", line 509, in dispatch
    response = self.handle_exception(exc)
               ^^^^^^^^^^^^^^^^^^^^^^^^^^
  File "e:\NAL-USDA\NAL_LIBRARY_SYSTEM\env\Lib\site-packages\rest_framework\views.py", line 469, in handle_exception
    self.raise_uncaught_exception(exc)
  File "e:\NAL-USDA\NAL_LIBRARY_SYSTEM\env\Lib\site-packages\rest_framework\views.py", line 480, in raise_uncaught_exception
    raise exc
  File "e:\NAL-USDA\NAL_LIBRARY_SYSTEM\env\Lib\site-packages\rest_framework\views.py", line 506, in dispatch
    response = handler(request, *args, **kwargs)
               ^^^^^^^^^^^^^^^^^^^^^^^^^^^^^^^^^
  File "e:\NAL-USDA\NAL_LIBRARY_SYSTEM\env\Lib\site-packages\rest_framework\mixins.py", line 19, in create
    self.perform_create(serializer)
  File "e:\NAL-USDA\NAL_LIBRARY_SYSTEM\env\Lib\site-packages\rest_framework\mixins.py", line 24, in perform_create
    serializer.save()
  File "e:\NAL-USDA\NAL_LIBRARY_SYSTEM\env\Lib\site-packages\rest_framework\serializers.py", line 212, in save
    self.instance = self.create(validated_data)
                    ^^^^^^^^^^^^^^^^^^^^^^^^^^^
  File "e:\NAL-USDA\NAL_LIBRARY_SYSTEM\env\Lib\site-packages\rest_framework\serializers.py", line 962, in create
    instance = ModelClass._default_manager.create(**validated_data)
               ^^^^^^^^^^^^^^^^^^^^^^^^^^^^^^^^^^^^^^^^^^^^^^^^^^^^
  File "e:\NAL-USDA\NAL_LIBRARY_SYSTEM\env\Lib\site-packages\django\db\models\manager.py", line 87, in manager_method
    return getattr(self.get_queryset(), name)(*args, **kwargs)
           ^^^^^^^^^^^^^^^^^^^^^^^^^^^^^^^^^^^^^^^^^^^^^^^^^^^
  File "e:\NAL-USDA\NAL_LIBRARY_SYSTEM\env\Lib\site-packages\django\db\models\query.py", line 658, in create
    obj.save(force_insert=True, using=self.db)
  File "E:\NAL-USDA\NAL_LIBRARY_SYSTEM\actions\providers.py", line 46, in save
    super(Provider_meta_data_FTP, self).save(*args, **kwargs)
  File "e:\NAL-USDA\NAL_LIBRARY_SYSTEM\env\Lib\site-packages\django\db\models\base.py", line 814, in save
    self.save_base(
  File "e:\NAL-USDA\NAL_LIBRARY_SYSTEM\env\Lib\site-packages\django\db\models\base.py", line 877, in save_base
    updated = self._save_table(
              ^^^^^^^^^^^^^^^^^
  File "e:\NAL-USDA\NAL_LIBRARY_SYSTEM\env\Lib\site-packages\django\db\models\base.py", line 1020, in _save_table
    results = self._do_insert(
              ^^^^^^^^^^^^^^^^
  File "e:\NAL-USDA\NAL_LIBRARY_SYSTEM\env\Lib\site-packages\django\db\models\base.py", line 1061, in _do_insert
    return manager._insert(
           ^^^^^^^^^^^^^^^^
  File "e:\NAL-USDA\NAL_LIBRARY_SYSTEM\env\Lib\site-packages\django\db\models\manager.py", line 87, in manager_method
    return getattr(self.get_queryset(), name)(*args, **kwargs)
           ^^^^^^^^^^^^^^^^^^^^^^^^^^^^^^^^^^^^^^^^^^^^^^^^^^^
  File "e:\NAL-USDA\NAL_LIBRARY_SYSTEM\env\Lib\site-packages\django\db\models\query.py", line 1805, in _insert
    return query.get_compiler(using=using).execute_sql(returning_fields)
           ^^^^^^^^^^^^^^^^^^^^^^^^^^^^^^^^^^^^^^^^^^^^^^^^^^^^^^^^^^^^^
  File "e:\NAL-USDA\NAL_LIBRARY_SYSTEM\env\Lib\site-packages\django\db\models\sql\compiler.py", line 1820, in execute_sql
    cursor.execute(sql, params)
  File "e:\NAL-USDA\NAL_LIBRARY_SYSTEM\env\Lib\site-packages\django\db\backends\utils.py", line 102, in execute
    return super().execute(sql, params)
           ^^^^^^^^^^^^^^^^^^^^^^^^^^^^
  File "e:\NAL-USDA\NAL_LIBRARY_SYSTEM\env\Lib\site-packages\django\db\backends\utils.py", line 67, in execute
    return self._execute_with_wrappers(
           ^^^^^^^^^^^^^^^^^^^^^^^^^^^^
  File "e:\NAL-USDA\NAL_LIBRARY_SYSTEM\env\Lib\site-packages\django\db\backends\utils.py", line 80, in _execute_with_wrappers
    return executor(sql, params, many, context)
           ^^^^^^^^^^^^^^^^^^^^^^^^^^^^^^^^^^^^
  File "e:\NAL-USDA\NAL_LIBRARY_SYSTEM\env\Lib\site-packages\django\db\backends\utils.py", line 84, in _execute
    with self.db.wrap_database_errors:
  File "e:\NAL-USDA\NAL_LIBRARY_SYSTEM\env\Lib\site-packages\django\db\utils.py", line 91, in __exit__
    raise dj_exc_value.with_traceback(traceback) from exc_value
  File "e:\NAL-USDA\NAL_LIBRARY_SYSTEM\env\Lib\site-packages\django\db\backends\utils.py", line 89, in _execute
    return self.cursor.execute(sql, params)
           ^^^^^^^^^^^^^^^^^^^^^^^^^^^^^^^^
  File "e:\NAL-USDA\NAL_LIBRARY_SYSTEM\env\Lib\site-packages\django\db\backends\mysql\base.py", line 75, in execute
    return self.cursor.execute(query, args)
           ^^^^^^^^^^^^^^^^^^^^^^^^^^^^^^^^
  File "e:\NAL-USDA\NAL_LIBRARY_SYSTEM\env\Lib\site-packages\MySQLdb\cursors.py", line 179, in execute
    res = self._query(mogrified_query)
          ^^^^^^^^^^^^^^^^^^^^^^^^^^^^
  File "e:\NAL-USDA\NAL_LIBRARY_SYSTEM\env\Lib\site-packages\MySQLdb\cursors.py", line 331, in _query
    self._do_get_result(db)
  File "e:\NAL-USDA\NAL_LIBRARY_SYSTEM\env\Lib\site-packages\MySQLdb\cursors.py", line 136, in _do_get_result
    self._result = result = self._get_result()
                            ^^^^^^^^^^^^^^^^^^
  File "e:\NAL-USDA\NAL_LIBRARY_SYSTEM\env\Lib\site-packages\MySQLdb\cursors.py", line 363, in _get_result
    return self._get_db().store_result()
           ^^^^^^^^^^^^^^^^^^^^^^^^^^^^^
django.db.utils.DataError: (1406, "Data too long for column 'password' at row 1")
ERROR 2024-02-22 20:41:30,828 basehttp 29064 3428 "POST /providers-ftp/ HTTP/1.1" 500 271762
ERROR 2024-02-22 20:42:31,593 log 29064 3428 Internal Server Error: /providers-ftp/
Traceback (most recent call last):
  File "e:\NAL-USDA\NAL_LIBRARY_SYSTEM\env\Lib\site-packages\django\db\backends\utils.py", line 89, in _execute
    return self.cursor.execute(sql, params)
           ^^^^^^^^^^^^^^^^^^^^^^^^^^^^^^^^
  File "e:\NAL-USDA\NAL_LIBRARY_SYSTEM\env\Lib\site-packages\django\db\backends\mysql\base.py", line 75, in execute
    return self.cursor.execute(query, args)
           ^^^^^^^^^^^^^^^^^^^^^^^^^^^^^^^^
  File "e:\NAL-USDA\NAL_LIBRARY_SYSTEM\env\Lib\site-packages\MySQLdb\cursors.py", line 179, in execute
    res = self._query(mogrified_query)
          ^^^^^^^^^^^^^^^^^^^^^^^^^^^^
  File "e:\NAL-USDA\NAL_LIBRARY_SYSTEM\env\Lib\site-packages\MySQLdb\cursors.py", line 331, in _query
    self._do_get_result(db)
  File "e:\NAL-USDA\NAL_LIBRARY_SYSTEM\env\Lib\site-packages\MySQLdb\cursors.py", line 136, in _do_get_result
    self._result = result = self._get_result()
                            ^^^^^^^^^^^^^^^^^^
  File "e:\NAL-USDA\NAL_LIBRARY_SYSTEM\env\Lib\site-packages\MySQLdb\cursors.py", line 363, in _get_result
    return self._get_db().store_result()
           ^^^^^^^^^^^^^^^^^^^^^^^^^^^^^
MySQLdb.DataError: (1406, "Data too long for column 'password' at row 1")

The above exception was the direct cause of the following exception:

Traceback (most recent call last):
  File "e:\NAL-USDA\NAL_LIBRARY_SYSTEM\env\Lib\site-packages\django\core\handlers\exception.py", line 55, in inner
    response = get_response(request)
               ^^^^^^^^^^^^^^^^^^^^^
  File "e:\NAL-USDA\NAL_LIBRARY_SYSTEM\env\Lib\site-packages\django\core\handlers\base.py", line 197, in _get_response
    response = wrapped_callback(request, *callback_args, **callback_kwargs)
               ^^^^^^^^^^^^^^^^^^^^^^^^^^^^^^^^^^^^^^^^^^^^^^^^^^^^^^^^^^^^
  File "e:\NAL-USDA\NAL_LIBRARY_SYSTEM\env\Lib\site-packages\django\views\decorators\csrf.py", line 56, in wrapper_view
    return view_func(*args, **kwargs)
           ^^^^^^^^^^^^^^^^^^^^^^^^^^
  File "e:\NAL-USDA\NAL_LIBRARY_SYSTEM\env\Lib\site-packages\rest_framework\viewsets.py", line 125, in view
    return self.dispatch(request, *args, **kwargs)
           ^^^^^^^^^^^^^^^^^^^^^^^^^^^^^^^^^^^^^^^
  File "e:\NAL-USDA\NAL_LIBRARY_SYSTEM\env\Lib\site-packages\rest_framework\views.py", line 509, in dispatch
    response = self.handle_exception(exc)
               ^^^^^^^^^^^^^^^^^^^^^^^^^^
  File "e:\NAL-USDA\NAL_LIBRARY_SYSTEM\env\Lib\site-packages\rest_framework\views.py", line 469, in handle_exception
    self.raise_uncaught_exception(exc)
  File "e:\NAL-USDA\NAL_LIBRARY_SYSTEM\env\Lib\site-packages\rest_framework\views.py", line 480, in raise_uncaught_exception
    raise exc
  File "e:\NAL-USDA\NAL_LIBRARY_SYSTEM\env\Lib\site-packages\rest_framework\views.py", line 506, in dispatch
    response = handler(request, *args, **kwargs)
               ^^^^^^^^^^^^^^^^^^^^^^^^^^^^^^^^^
  File "e:\NAL-USDA\NAL_LIBRARY_SYSTEM\env\Lib\site-packages\rest_framework\mixins.py", line 19, in create
    self.perform_create(serializer)
  File "e:\NAL-USDA\NAL_LIBRARY_SYSTEM\env\Lib\site-packages\rest_framework\mixins.py", line 24, in perform_create
    serializer.save()
  File "e:\NAL-USDA\NAL_LIBRARY_SYSTEM\env\Lib\site-packages\rest_framework\serializers.py", line 212, in save
    self.instance = self.create(validated_data)
                    ^^^^^^^^^^^^^^^^^^^^^^^^^^^
  File "e:\NAL-USDA\NAL_LIBRARY_SYSTEM\env\Lib\site-packages\rest_framework\serializers.py", line 962, in create
    instance = ModelClass._default_manager.create(**validated_data)
               ^^^^^^^^^^^^^^^^^^^^^^^^^^^^^^^^^^^^^^^^^^^^^^^^^^^^
  File "e:\NAL-USDA\NAL_LIBRARY_SYSTEM\env\Lib\site-packages\django\db\models\manager.py", line 87, in manager_method
    return getattr(self.get_queryset(), name)(*args, **kwargs)
           ^^^^^^^^^^^^^^^^^^^^^^^^^^^^^^^^^^^^^^^^^^^^^^^^^^^
  File "e:\NAL-USDA\NAL_LIBRARY_SYSTEM\env\Lib\site-packages\django\db\models\query.py", line 658, in create
    obj.save(force_insert=True, using=self.db)
  File "E:\NAL-USDA\NAL_LIBRARY_SYSTEM\actions\providers.py", line 46, in save
    super(Provider_meta_data_FTP, self).save(*args, **kwargs)
  File "e:\NAL-USDA\NAL_LIBRARY_SYSTEM\env\Lib\site-packages\django\db\models\base.py", line 814, in save
    self.save_base(
  File "e:\NAL-USDA\NAL_LIBRARY_SYSTEM\env\Lib\site-packages\django\db\models\base.py", line 877, in save_base
    updated = self._save_table(
              ^^^^^^^^^^^^^^^^^
  File "e:\NAL-USDA\NAL_LIBRARY_SYSTEM\env\Lib\site-packages\django\db\models\base.py", line 1020, in _save_table
    results = self._do_insert(
              ^^^^^^^^^^^^^^^^
  File "e:\NAL-USDA\NAL_LIBRARY_SYSTEM\env\Lib\site-packages\django\db\models\base.py", line 1061, in _do_insert
    return manager._insert(
           ^^^^^^^^^^^^^^^^
  File "e:\NAL-USDA\NAL_LIBRARY_SYSTEM\env\Lib\site-packages\django\db\models\manager.py", line 87, in manager_method
    return getattr(self.get_queryset(), name)(*args, **kwargs)
           ^^^^^^^^^^^^^^^^^^^^^^^^^^^^^^^^^^^^^^^^^^^^^^^^^^^
  File "e:\NAL-USDA\NAL_LIBRARY_SYSTEM\env\Lib\site-packages\django\db\models\query.py", line 1805, in _insert
    return query.get_compiler(using=using).execute_sql(returning_fields)
           ^^^^^^^^^^^^^^^^^^^^^^^^^^^^^^^^^^^^^^^^^^^^^^^^^^^^^^^^^^^^^
  File "e:\NAL-USDA\NAL_LIBRARY_SYSTEM\env\Lib\site-packages\django\db\models\sql\compiler.py", line 1820, in execute_sql
    cursor.execute(sql, params)
  File "e:\NAL-USDA\NAL_LIBRARY_SYSTEM\env\Lib\site-packages\django\db\backends\utils.py", line 102, in execute
    return super().execute(sql, params)
           ^^^^^^^^^^^^^^^^^^^^^^^^^^^^
  File "e:\NAL-USDA\NAL_LIBRARY_SYSTEM\env\Lib\site-packages\django\db\backends\utils.py", line 67, in execute
    return self._execute_with_wrappers(
           ^^^^^^^^^^^^^^^^^^^^^^^^^^^^
  File "e:\NAL-USDA\NAL_LIBRARY_SYSTEM\env\Lib\site-packages\django\db\backends\utils.py", line 80, in _execute_with_wrappers
    return executor(sql, params, many, context)
           ^^^^^^^^^^^^^^^^^^^^^^^^^^^^^^^^^^^^
  File "e:\NAL-USDA\NAL_LIBRARY_SYSTEM\env\Lib\site-packages\django\db\backends\utils.py", line 84, in _execute
    with self.db.wrap_database_errors:
  File "e:\NAL-USDA\NAL_LIBRARY_SYSTEM\env\Lib\site-packages\django\db\utils.py", line 91, in __exit__
    raise dj_exc_value.with_traceback(traceback) from exc_value
  File "e:\NAL-USDA\NAL_LIBRARY_SYSTEM\env\Lib\site-packages\django\db\backends\utils.py", line 89, in _execute
    return self.cursor.execute(sql, params)
           ^^^^^^^^^^^^^^^^^^^^^^^^^^^^^^^^
  File "e:\NAL-USDA\NAL_LIBRARY_SYSTEM\env\Lib\site-packages\django\db\backends\mysql\base.py", line 75, in execute
    return self.cursor.execute(query, args)
           ^^^^^^^^^^^^^^^^^^^^^^^^^^^^^^^^
  File "e:\NAL-USDA\NAL_LIBRARY_SYSTEM\env\Lib\site-packages\MySQLdb\cursors.py", line 179, in execute
    res = self._query(mogrified_query)
          ^^^^^^^^^^^^^^^^^^^^^^^^^^^^
  File "e:\NAL-USDA\NAL_LIBRARY_SYSTEM\env\Lib\site-packages\MySQLdb\cursors.py", line 331, in _query
    self._do_get_result(db)
  File "e:\NAL-USDA\NAL_LIBRARY_SYSTEM\env\Lib\site-packages\MySQLdb\cursors.py", line 136, in _do_get_result
    self._result = result = self._get_result()
                            ^^^^^^^^^^^^^^^^^^
  File "e:\NAL-USDA\NAL_LIBRARY_SYSTEM\env\Lib\site-packages\MySQLdb\cursors.py", line 363, in _get_result
    return self._get_db().store_result()
           ^^^^^^^^^^^^^^^^^^^^^^^^^^^^^
django.db.utils.DataError: (1406, "Data too long for column 'password' at row 1")
ERROR 2024-02-22 20:42:31,601 basehttp 29064 3428 "POST /providers-ftp/ HTTP/1.1" 500 271631
ERROR 2024-02-22 20:43:11,615 log 29064 3428 Internal Server Error: /providers-ftp/
Traceback (most recent call last):
  File "e:\NAL-USDA\NAL_LIBRARY_SYSTEM\env\Lib\site-packages\django\db\backends\utils.py", line 89, in _execute
    return self.cursor.execute(sql, params)
           ^^^^^^^^^^^^^^^^^^^^^^^^^^^^^^^^
  File "e:\NAL-USDA\NAL_LIBRARY_SYSTEM\env\Lib\site-packages\django\db\backends\mysql\base.py", line 75, in execute
    return self.cursor.execute(query, args)
           ^^^^^^^^^^^^^^^^^^^^^^^^^^^^^^^^
  File "e:\NAL-USDA\NAL_LIBRARY_SYSTEM\env\Lib\site-packages\MySQLdb\cursors.py", line 179, in execute
    res = self._query(mogrified_query)
          ^^^^^^^^^^^^^^^^^^^^^^^^^^^^
  File "e:\NAL-USDA\NAL_LIBRARY_SYSTEM\env\Lib\site-packages\MySQLdb\cursors.py", line 331, in _query
    self._do_get_result(db)
  File "e:\NAL-USDA\NAL_LIBRARY_SYSTEM\env\Lib\site-packages\MySQLdb\cursors.py", line 136, in _do_get_result
    self._result = result = self._get_result()
                            ^^^^^^^^^^^^^^^^^^
  File "e:\NAL-USDA\NAL_LIBRARY_SYSTEM\env\Lib\site-packages\MySQLdb\cursors.py", line 363, in _get_result
    return self._get_db().store_result()
           ^^^^^^^^^^^^^^^^^^^^^^^^^^^^^
MySQLdb.DataError: (1406, "Data too long for column 'password' at row 1")

The above exception was the direct cause of the following exception:

Traceback (most recent call last):
  File "e:\NAL-USDA\NAL_LIBRARY_SYSTEM\env\Lib\site-packages\django\core\handlers\exception.py", line 55, in inner
    response = get_response(request)
               ^^^^^^^^^^^^^^^^^^^^^
  File "e:\NAL-USDA\NAL_LIBRARY_SYSTEM\env\Lib\site-packages\django\core\handlers\base.py", line 197, in _get_response
    response = wrapped_callback(request, *callback_args, **callback_kwargs)
               ^^^^^^^^^^^^^^^^^^^^^^^^^^^^^^^^^^^^^^^^^^^^^^^^^^^^^^^^^^^^
  File "e:\NAL-USDA\NAL_LIBRARY_SYSTEM\env\Lib\site-packages\django\views\decorators\csrf.py", line 56, in wrapper_view
    return view_func(*args, **kwargs)
           ^^^^^^^^^^^^^^^^^^^^^^^^^^
  File "e:\NAL-USDA\NAL_LIBRARY_SYSTEM\env\Lib\site-packages\rest_framework\viewsets.py", line 125, in view
    return self.dispatch(request, *args, **kwargs)
           ^^^^^^^^^^^^^^^^^^^^^^^^^^^^^^^^^^^^^^^
  File "e:\NAL-USDA\NAL_LIBRARY_SYSTEM\env\Lib\site-packages\rest_framework\views.py", line 509, in dispatch
    response = self.handle_exception(exc)
               ^^^^^^^^^^^^^^^^^^^^^^^^^^
  File "e:\NAL-USDA\NAL_LIBRARY_SYSTEM\env\Lib\site-packages\rest_framework\views.py", line 469, in handle_exception
    self.raise_uncaught_exception(exc)
  File "e:\NAL-USDA\NAL_LIBRARY_SYSTEM\env\Lib\site-packages\rest_framework\views.py", line 480, in raise_uncaught_exception
    raise exc
  File "e:\NAL-USDA\NAL_LIBRARY_SYSTEM\env\Lib\site-packages\rest_framework\views.py", line 506, in dispatch
    response = handler(request, *args, **kwargs)
               ^^^^^^^^^^^^^^^^^^^^^^^^^^^^^^^^^
  File "e:\NAL-USDA\NAL_LIBRARY_SYSTEM\env\Lib\site-packages\rest_framework\mixins.py", line 19, in create
    self.perform_create(serializer)
  File "e:\NAL-USDA\NAL_LIBRARY_SYSTEM\env\Lib\site-packages\rest_framework\mixins.py", line 24, in perform_create
    serializer.save()
  File "e:\NAL-USDA\NAL_LIBRARY_SYSTEM\env\Lib\site-packages\rest_framework\serializers.py", line 212, in save
    self.instance = self.create(validated_data)
                    ^^^^^^^^^^^^^^^^^^^^^^^^^^^
  File "e:\NAL-USDA\NAL_LIBRARY_SYSTEM\env\Lib\site-packages\rest_framework\serializers.py", line 962, in create
    instance = ModelClass._default_manager.create(**validated_data)
               ^^^^^^^^^^^^^^^^^^^^^^^^^^^^^^^^^^^^^^^^^^^^^^^^^^^^
  File "e:\NAL-USDA\NAL_LIBRARY_SYSTEM\env\Lib\site-packages\django\db\models\manager.py", line 87, in manager_method
    return getattr(self.get_queryset(), name)(*args, **kwargs)
           ^^^^^^^^^^^^^^^^^^^^^^^^^^^^^^^^^^^^^^^^^^^^^^^^^^^
  File "e:\NAL-USDA\NAL_LIBRARY_SYSTEM\env\Lib\site-packages\django\db\models\query.py", line 658, in create
    obj.save(force_insert=True, using=self.db)
  File "E:\NAL-USDA\NAL_LIBRARY_SYSTEM\actions\providers.py", line 46, in save
    super(Provider_meta_data_FTP, self).save(*args, **kwargs)
  File "e:\NAL-USDA\NAL_LIBRARY_SYSTEM\env\Lib\site-packages\django\db\models\base.py", line 814, in save
    self.save_base(
  File "e:\NAL-USDA\NAL_LIBRARY_SYSTEM\env\Lib\site-packages\django\db\models\base.py", line 877, in save_base
    updated = self._save_table(
              ^^^^^^^^^^^^^^^^^
  File "e:\NAL-USDA\NAL_LIBRARY_SYSTEM\env\Lib\site-packages\django\db\models\base.py", line 1020, in _save_table
    results = self._do_insert(
              ^^^^^^^^^^^^^^^^
  File "e:\NAL-USDA\NAL_LIBRARY_SYSTEM\env\Lib\site-packages\django\db\models\base.py", line 1061, in _do_insert
    return manager._insert(
           ^^^^^^^^^^^^^^^^
  File "e:\NAL-USDA\NAL_LIBRARY_SYSTEM\env\Lib\site-packages\django\db\models\manager.py", line 87, in manager_method
    return getattr(self.get_queryset(), name)(*args, **kwargs)
           ^^^^^^^^^^^^^^^^^^^^^^^^^^^^^^^^^^^^^^^^^^^^^^^^^^^
  File "e:\NAL-USDA\NAL_LIBRARY_SYSTEM\env\Lib\site-packages\django\db\models\query.py", line 1805, in _insert
    return query.get_compiler(using=using).execute_sql(returning_fields)
           ^^^^^^^^^^^^^^^^^^^^^^^^^^^^^^^^^^^^^^^^^^^^^^^^^^^^^^^^^^^^^
  File "e:\NAL-USDA\NAL_LIBRARY_SYSTEM\env\Lib\site-packages\django\db\models\sql\compiler.py", line 1820, in execute_sql
    cursor.execute(sql, params)
  File "e:\NAL-USDA\NAL_LIBRARY_SYSTEM\env\Lib\site-packages\django\db\backends\utils.py", line 102, in execute
    return super().execute(sql, params)
           ^^^^^^^^^^^^^^^^^^^^^^^^^^^^
  File "e:\NAL-USDA\NAL_LIBRARY_SYSTEM\env\Lib\site-packages\django\db\backends\utils.py", line 67, in execute
    return self._execute_with_wrappers(
           ^^^^^^^^^^^^^^^^^^^^^^^^^^^^
  File "e:\NAL-USDA\NAL_LIBRARY_SYSTEM\env\Lib\site-packages\django\db\backends\utils.py", line 80, in _execute_with_wrappers
    return executor(sql, params, many, context)
           ^^^^^^^^^^^^^^^^^^^^^^^^^^^^^^^^^^^^
  File "e:\NAL-USDA\NAL_LIBRARY_SYSTEM\env\Lib\site-packages\django\db\backends\utils.py", line 84, in _execute
    with self.db.wrap_database_errors:
  File "e:\NAL-USDA\NAL_LIBRARY_SYSTEM\env\Lib\site-packages\django\db\utils.py", line 91, in __exit__
    raise dj_exc_value.with_traceback(traceback) from exc_value
  File "e:\NAL-USDA\NAL_LIBRARY_SYSTEM\env\Lib\site-packages\django\db\backends\utils.py", line 89, in _execute
    return self.cursor.execute(sql, params)
           ^^^^^^^^^^^^^^^^^^^^^^^^^^^^^^^^
  File "e:\NAL-USDA\NAL_LIBRARY_SYSTEM\env\Lib\site-packages\django\db\backends\mysql\base.py", line 75, in execute
    return self.cursor.execute(query, args)
           ^^^^^^^^^^^^^^^^^^^^^^^^^^^^^^^^
  File "e:\NAL-USDA\NAL_LIBRARY_SYSTEM\env\Lib\site-packages\MySQLdb\cursors.py", line 179, in execute
    res = self._query(mogrified_query)
          ^^^^^^^^^^^^^^^^^^^^^^^^^^^^
  File "e:\NAL-USDA\NAL_LIBRARY_SYSTEM\env\Lib\site-packages\MySQLdb\cursors.py", line 331, in _query
    self._do_get_result(db)
  File "e:\NAL-USDA\NAL_LIBRARY_SYSTEM\env\Lib\site-packages\MySQLdb\cursors.py", line 136, in _do_get_result
    self._result = result = self._get_result()
                            ^^^^^^^^^^^^^^^^^^
  File "e:\NAL-USDA\NAL_LIBRARY_SYSTEM\env\Lib\site-packages\MySQLdb\cursors.py", line 363, in _get_result
    return self._get_db().store_result()
           ^^^^^^^^^^^^^^^^^^^^^^^^^^^^^
django.db.utils.DataError: (1406, "Data too long for column 'password' at row 1")
ERROR 2024-02-22 20:43:11,623 basehttp 29064 3428 "POST /providers-ftp/ HTTP/1.1" 500 271763
ERROR 2024-02-22 20:43:53,078 log 8512 27584 Internal Server Error: /providers-ftp/
Traceback (most recent call last):
  File "e:\NAL-USDA\NAL_LIBRARY_SYSTEM\env\Lib\site-packages\django\db\backends\utils.py", line 89, in _execute
    return self.cursor.execute(sql, params)
           ^^^^^^^^^^^^^^^^^^^^^^^^^^^^^^^^
  File "e:\NAL-USDA\NAL_LIBRARY_SYSTEM\env\Lib\site-packages\django\db\backends\mysql\base.py", line 75, in execute
    return self.cursor.execute(query, args)
           ^^^^^^^^^^^^^^^^^^^^^^^^^^^^^^^^
  File "e:\NAL-USDA\NAL_LIBRARY_SYSTEM\env\Lib\site-packages\MySQLdb\cursors.py", line 179, in execute
    res = self._query(mogrified_query)
          ^^^^^^^^^^^^^^^^^^^^^^^^^^^^
  File "e:\NAL-USDA\NAL_LIBRARY_SYSTEM\env\Lib\site-packages\MySQLdb\cursors.py", line 331, in _query
    self._do_get_result(db)
  File "e:\NAL-USDA\NAL_LIBRARY_SYSTEM\env\Lib\site-packages\MySQLdb\cursors.py", line 136, in _do_get_result
    self._result = result = self._get_result()
                            ^^^^^^^^^^^^^^^^^^
  File "e:\NAL-USDA\NAL_LIBRARY_SYSTEM\env\Lib\site-packages\MySQLdb\cursors.py", line 363, in _get_result
    return self._get_db().store_result()
           ^^^^^^^^^^^^^^^^^^^^^^^^^^^^^
MySQLdb.DataError: (1406, "Data too long for column 'password' at row 1")

The above exception was the direct cause of the following exception:

Traceback (most recent call last):
  File "e:\NAL-USDA\NAL_LIBRARY_SYSTEM\env\Lib\site-packages\django\core\handlers\exception.py", line 55, in inner
    response = get_response(request)
               ^^^^^^^^^^^^^^^^^^^^^
  File "e:\NAL-USDA\NAL_LIBRARY_SYSTEM\env\Lib\site-packages\django\core\handlers\base.py", line 197, in _get_response
    response = wrapped_callback(request, *callback_args, **callback_kwargs)
               ^^^^^^^^^^^^^^^^^^^^^^^^^^^^^^^^^^^^^^^^^^^^^^^^^^^^^^^^^^^^
  File "e:\NAL-USDA\NAL_LIBRARY_SYSTEM\env\Lib\site-packages\django\views\decorators\csrf.py", line 56, in wrapper_view
    return view_func(*args, **kwargs)
           ^^^^^^^^^^^^^^^^^^^^^^^^^^
  File "e:\NAL-USDA\NAL_LIBRARY_SYSTEM\env\Lib\site-packages\rest_framework\viewsets.py", line 125, in view
    return self.dispatch(request, *args, **kwargs)
           ^^^^^^^^^^^^^^^^^^^^^^^^^^^^^^^^^^^^^^^
  File "e:\NAL-USDA\NAL_LIBRARY_SYSTEM\env\Lib\site-packages\rest_framework\views.py", line 509, in dispatch
    response = self.handle_exception(exc)
               ^^^^^^^^^^^^^^^^^^^^^^^^^^
  File "e:\NAL-USDA\NAL_LIBRARY_SYSTEM\env\Lib\site-packages\rest_framework\views.py", line 469, in handle_exception
    self.raise_uncaught_exception(exc)
  File "e:\NAL-USDA\NAL_LIBRARY_SYSTEM\env\Lib\site-packages\rest_framework\views.py", line 480, in raise_uncaught_exception
    raise exc
  File "e:\NAL-USDA\NAL_LIBRARY_SYSTEM\env\Lib\site-packages\rest_framework\views.py", line 506, in dispatch
    response = handler(request, *args, **kwargs)
               ^^^^^^^^^^^^^^^^^^^^^^^^^^^^^^^^^
  File "e:\NAL-USDA\NAL_LIBRARY_SYSTEM\env\Lib\site-packages\rest_framework\mixins.py", line 19, in create
    self.perform_create(serializer)
  File "e:\NAL-USDA\NAL_LIBRARY_SYSTEM\env\Lib\site-packages\rest_framework\mixins.py", line 24, in perform_create
    serializer.save()
  File "e:\NAL-USDA\NAL_LIBRARY_SYSTEM\env\Lib\site-packages\rest_framework\serializers.py", line 212, in save
    self.instance = self.create(validated_data)
                    ^^^^^^^^^^^^^^^^^^^^^^^^^^^
  File "e:\NAL-USDA\NAL_LIBRARY_SYSTEM\env\Lib\site-packages\rest_framework\serializers.py", line 962, in create
    instance = ModelClass._default_manager.create(**validated_data)
               ^^^^^^^^^^^^^^^^^^^^^^^^^^^^^^^^^^^^^^^^^^^^^^^^^^^^
  File "e:\NAL-USDA\NAL_LIBRARY_SYSTEM\env\Lib\site-packages\django\db\models\manager.py", line 87, in manager_method
    return getattr(self.get_queryset(), name)(*args, **kwargs)
           ^^^^^^^^^^^^^^^^^^^^^^^^^^^^^^^^^^^^^^^^^^^^^^^^^^^
  File "e:\NAL-USDA\NAL_LIBRARY_SYSTEM\env\Lib\site-packages\django\db\models\query.py", line 658, in create
    obj.save(force_insert=True, using=self.db)
  File "E:\NAL-USDA\NAL_LIBRARY_SYSTEM\actions\providers.py", line 46, in save
    super(Provider_meta_data_FTP, self).save(*args, **kwargs)
  File "e:\NAL-USDA\NAL_LIBRARY_SYSTEM\env\Lib\site-packages\django\db\models\base.py", line 814, in save
    self.save_base(
  File "e:\NAL-USDA\NAL_LIBRARY_SYSTEM\env\Lib\site-packages\django\db\models\base.py", line 877, in save_base
    updated = self._save_table(
              ^^^^^^^^^^^^^^^^^
  File "e:\NAL-USDA\NAL_LIBRARY_SYSTEM\env\Lib\site-packages\django\db\models\base.py", line 1020, in _save_table
    results = self._do_insert(
              ^^^^^^^^^^^^^^^^
  File "e:\NAL-USDA\NAL_LIBRARY_SYSTEM\env\Lib\site-packages\django\db\models\base.py", line 1061, in _do_insert
    return manager._insert(
           ^^^^^^^^^^^^^^^^
  File "e:\NAL-USDA\NAL_LIBRARY_SYSTEM\env\Lib\site-packages\django\db\models\manager.py", line 87, in manager_method
    return getattr(self.get_queryset(), name)(*args, **kwargs)
           ^^^^^^^^^^^^^^^^^^^^^^^^^^^^^^^^^^^^^^^^^^^^^^^^^^^
  File "e:\NAL-USDA\NAL_LIBRARY_SYSTEM\env\Lib\site-packages\django\db\models\query.py", line 1805, in _insert
    return query.get_compiler(using=using).execute_sql(returning_fields)
           ^^^^^^^^^^^^^^^^^^^^^^^^^^^^^^^^^^^^^^^^^^^^^^^^^^^^^^^^^^^^^
  File "e:\NAL-USDA\NAL_LIBRARY_SYSTEM\env\Lib\site-packages\django\db\models\sql\compiler.py", line 1820, in execute_sql
    cursor.execute(sql, params)
  File "e:\NAL-USDA\NAL_LIBRARY_SYSTEM\env\Lib\site-packages\django\db\backends\utils.py", line 102, in execute
    return super().execute(sql, params)
           ^^^^^^^^^^^^^^^^^^^^^^^^^^^^
  File "e:\NAL-USDA\NAL_LIBRARY_SYSTEM\env\Lib\site-packages\django\db\backends\utils.py", line 67, in execute
    return self._execute_with_wrappers(
           ^^^^^^^^^^^^^^^^^^^^^^^^^^^^
  File "e:\NAL-USDA\NAL_LIBRARY_SYSTEM\env\Lib\site-packages\django\db\backends\utils.py", line 80, in _execute_with_wrappers
    return executor(sql, params, many, context)
           ^^^^^^^^^^^^^^^^^^^^^^^^^^^^^^^^^^^^
  File "e:\NAL-USDA\NAL_LIBRARY_SYSTEM\env\Lib\site-packages\django\db\backends\utils.py", line 84, in _execute
    with self.db.wrap_database_errors:
  File "e:\NAL-USDA\NAL_LIBRARY_SYSTEM\env\Lib\site-packages\django\db\utils.py", line 91, in __exit__
    raise dj_exc_value.with_traceback(traceback) from exc_value
  File "e:\NAL-USDA\NAL_LIBRARY_SYSTEM\env\Lib\site-packages\django\db\backends\utils.py", line 89, in _execute
    return self.cursor.execute(sql, params)
           ^^^^^^^^^^^^^^^^^^^^^^^^^^^^^^^^
  File "e:\NAL-USDA\NAL_LIBRARY_SYSTEM\env\Lib\site-packages\django\db\backends\mysql\base.py", line 75, in execute
    return self.cursor.execute(query, args)
           ^^^^^^^^^^^^^^^^^^^^^^^^^^^^^^^^
  File "e:\NAL-USDA\NAL_LIBRARY_SYSTEM\env\Lib\site-packages\MySQLdb\cursors.py", line 179, in execute
    res = self._query(mogrified_query)
          ^^^^^^^^^^^^^^^^^^^^^^^^^^^^
  File "e:\NAL-USDA\NAL_LIBRARY_SYSTEM\env\Lib\site-packages\MySQLdb\cursors.py", line 331, in _query
    self._do_get_result(db)
  File "e:\NAL-USDA\NAL_LIBRARY_SYSTEM\env\Lib\site-packages\MySQLdb\cursors.py", line 136, in _do_get_result
    self._result = result = self._get_result()
                            ^^^^^^^^^^^^^^^^^^
  File "e:\NAL-USDA\NAL_LIBRARY_SYSTEM\env\Lib\site-packages\MySQLdb\cursors.py", line 363, in _get_result
    return self._get_db().store_result()
           ^^^^^^^^^^^^^^^^^^^^^^^^^^^^^
django.db.utils.DataError: (1406, "Data too long for column 'password' at row 1")
ERROR 2024-02-22 20:43:53,095 basehttp 8512 27584 "POST /providers-ftp/ HTTP/1.1" 500 271820
ERROR 2024-02-22 20:44:05,752 log 8512 27584 Internal Server Error: /providers-ftp/
Traceback (most recent call last):
  File "e:\NAL-USDA\NAL_LIBRARY_SYSTEM\env\Lib\site-packages\django\db\backends\utils.py", line 89, in _execute
    return self.cursor.execute(sql, params)
           ^^^^^^^^^^^^^^^^^^^^^^^^^^^^^^^^
  File "e:\NAL-USDA\NAL_LIBRARY_SYSTEM\env\Lib\site-packages\django\db\backends\mysql\base.py", line 75, in execute
    return self.cursor.execute(query, args)
           ^^^^^^^^^^^^^^^^^^^^^^^^^^^^^^^^
  File "e:\NAL-USDA\NAL_LIBRARY_SYSTEM\env\Lib\site-packages\MySQLdb\cursors.py", line 179, in execute
    res = self._query(mogrified_query)
          ^^^^^^^^^^^^^^^^^^^^^^^^^^^^
  File "e:\NAL-USDA\NAL_LIBRARY_SYSTEM\env\Lib\site-packages\MySQLdb\cursors.py", line 331, in _query
    self._do_get_result(db)
  File "e:\NAL-USDA\NAL_LIBRARY_SYSTEM\env\Lib\site-packages\MySQLdb\cursors.py", line 136, in _do_get_result
    self._result = result = self._get_result()
                            ^^^^^^^^^^^^^^^^^^
  File "e:\NAL-USDA\NAL_LIBRARY_SYSTEM\env\Lib\site-packages\MySQLdb\cursors.py", line 363, in _get_result
    return self._get_db().store_result()
           ^^^^^^^^^^^^^^^^^^^^^^^^^^^^^
MySQLdb.DataError: (1406, "Data too long for column 'password' at row 1")

The above exception was the direct cause of the following exception:

Traceback (most recent call last):
  File "e:\NAL-USDA\NAL_LIBRARY_SYSTEM\env\Lib\site-packages\django\core\handlers\exception.py", line 55, in inner
    response = get_response(request)
               ^^^^^^^^^^^^^^^^^^^^^
  File "e:\NAL-USDA\NAL_LIBRARY_SYSTEM\env\Lib\site-packages\django\core\handlers\base.py", line 197, in _get_response
    response = wrapped_callback(request, *callback_args, **callback_kwargs)
               ^^^^^^^^^^^^^^^^^^^^^^^^^^^^^^^^^^^^^^^^^^^^^^^^^^^^^^^^^^^^
  File "e:\NAL-USDA\NAL_LIBRARY_SYSTEM\env\Lib\site-packages\django\views\decorators\csrf.py", line 56, in wrapper_view
    return view_func(*args, **kwargs)
           ^^^^^^^^^^^^^^^^^^^^^^^^^^
  File "e:\NAL-USDA\NAL_LIBRARY_SYSTEM\env\Lib\site-packages\rest_framework\viewsets.py", line 125, in view
    return self.dispatch(request, *args, **kwargs)
           ^^^^^^^^^^^^^^^^^^^^^^^^^^^^^^^^^^^^^^^
  File "e:\NAL-USDA\NAL_LIBRARY_SYSTEM\env\Lib\site-packages\rest_framework\views.py", line 509, in dispatch
    response = self.handle_exception(exc)
               ^^^^^^^^^^^^^^^^^^^^^^^^^^
  File "e:\NAL-USDA\NAL_LIBRARY_SYSTEM\env\Lib\site-packages\rest_framework\views.py", line 469, in handle_exception
    self.raise_uncaught_exception(exc)
  File "e:\NAL-USDA\NAL_LIBRARY_SYSTEM\env\Lib\site-packages\rest_framework\views.py", line 480, in raise_uncaught_exception
    raise exc
  File "e:\NAL-USDA\NAL_LIBRARY_SYSTEM\env\Lib\site-packages\rest_framework\views.py", line 506, in dispatch
    response = handler(request, *args, **kwargs)
               ^^^^^^^^^^^^^^^^^^^^^^^^^^^^^^^^^
  File "e:\NAL-USDA\NAL_LIBRARY_SYSTEM\env\Lib\site-packages\rest_framework\mixins.py", line 19, in create
    self.perform_create(serializer)
  File "e:\NAL-USDA\NAL_LIBRARY_SYSTEM\env\Lib\site-packages\rest_framework\mixins.py", line 24, in perform_create
    serializer.save()
  File "e:\NAL-USDA\NAL_LIBRARY_SYSTEM\env\Lib\site-packages\rest_framework\serializers.py", line 212, in save
    self.instance = self.create(validated_data)
                    ^^^^^^^^^^^^^^^^^^^^^^^^^^^
  File "e:\NAL-USDA\NAL_LIBRARY_SYSTEM\env\Lib\site-packages\rest_framework\serializers.py", line 962, in create
    instance = ModelClass._default_manager.create(**validated_data)
               ^^^^^^^^^^^^^^^^^^^^^^^^^^^^^^^^^^^^^^^^^^^^^^^^^^^^
  File "e:\NAL-USDA\NAL_LIBRARY_SYSTEM\env\Lib\site-packages\django\db\models\manager.py", line 87, in manager_method
    return getattr(self.get_queryset(), name)(*args, **kwargs)
           ^^^^^^^^^^^^^^^^^^^^^^^^^^^^^^^^^^^^^^^^^^^^^^^^^^^
  File "e:\NAL-USDA\NAL_LIBRARY_SYSTEM\env\Lib\site-packages\django\db\models\query.py", line 658, in create
    obj.save(force_insert=True, using=self.db)
  File "E:\NAL-USDA\NAL_LIBRARY_SYSTEM\actions\providers.py", line 46, in save
    super(Provider_meta_data_FTP, self).save(*args, **kwargs)
  File "e:\NAL-USDA\NAL_LIBRARY_SYSTEM\env\Lib\site-packages\django\db\models\base.py", line 814, in save
    self.save_base(
  File "e:\NAL-USDA\NAL_LIBRARY_SYSTEM\env\Lib\site-packages\django\db\models\base.py", line 877, in save_base
    updated = self._save_table(
              ^^^^^^^^^^^^^^^^^
  File "e:\NAL-USDA\NAL_LIBRARY_SYSTEM\env\Lib\site-packages\django\db\models\base.py", line 1020, in _save_table
    results = self._do_insert(
              ^^^^^^^^^^^^^^^^
  File "e:\NAL-USDA\NAL_LIBRARY_SYSTEM\env\Lib\site-packages\django\db\models\base.py", line 1061, in _do_insert
    return manager._insert(
           ^^^^^^^^^^^^^^^^
  File "e:\NAL-USDA\NAL_LIBRARY_SYSTEM\env\Lib\site-packages\django\db\models\manager.py", line 87, in manager_method
    return getattr(self.get_queryset(), name)(*args, **kwargs)
           ^^^^^^^^^^^^^^^^^^^^^^^^^^^^^^^^^^^^^^^^^^^^^^^^^^^
  File "e:\NAL-USDA\NAL_LIBRARY_SYSTEM\env\Lib\site-packages\django\db\models\query.py", line 1805, in _insert
    return query.get_compiler(using=using).execute_sql(returning_fields)
           ^^^^^^^^^^^^^^^^^^^^^^^^^^^^^^^^^^^^^^^^^^^^^^^^^^^^^^^^^^^^^
  File "e:\NAL-USDA\NAL_LIBRARY_SYSTEM\env\Lib\site-packages\django\db\models\sql\compiler.py", line 1820, in execute_sql
    cursor.execute(sql, params)
  File "e:\NAL-USDA\NAL_LIBRARY_SYSTEM\env\Lib\site-packages\django\db\backends\utils.py", line 102, in execute
    return super().execute(sql, params)
           ^^^^^^^^^^^^^^^^^^^^^^^^^^^^
  File "e:\NAL-USDA\NAL_LIBRARY_SYSTEM\env\Lib\site-packages\django\db\backends\utils.py", line 67, in execute
    return self._execute_with_wrappers(
           ^^^^^^^^^^^^^^^^^^^^^^^^^^^^
  File "e:\NAL-USDA\NAL_LIBRARY_SYSTEM\env\Lib\site-packages\django\db\backends\utils.py", line 80, in _execute_with_wrappers
    return executor(sql, params, many, context)
           ^^^^^^^^^^^^^^^^^^^^^^^^^^^^^^^^^^^^
  File "e:\NAL-USDA\NAL_LIBRARY_SYSTEM\env\Lib\site-packages\django\db\backends\utils.py", line 84, in _execute
    with self.db.wrap_database_errors:
  File "e:\NAL-USDA\NAL_LIBRARY_SYSTEM\env\Lib\site-packages\django\db\utils.py", line 91, in __exit__
    raise dj_exc_value.with_traceback(traceback) from exc_value
  File "e:\NAL-USDA\NAL_LIBRARY_SYSTEM\env\Lib\site-packages\django\db\backends\utils.py", line 89, in _execute
    return self.cursor.execute(sql, params)
           ^^^^^^^^^^^^^^^^^^^^^^^^^^^^^^^^
  File "e:\NAL-USDA\NAL_LIBRARY_SYSTEM\env\Lib\site-packages\django\db\backends\mysql\base.py", line 75, in execute
    return self.cursor.execute(query, args)
           ^^^^^^^^^^^^^^^^^^^^^^^^^^^^^^^^
  File "e:\NAL-USDA\NAL_LIBRARY_SYSTEM\env\Lib\site-packages\MySQLdb\cursors.py", line 179, in execute
    res = self._query(mogrified_query)
          ^^^^^^^^^^^^^^^^^^^^^^^^^^^^
  File "e:\NAL-USDA\NAL_LIBRARY_SYSTEM\env\Lib\site-packages\MySQLdb\cursors.py", line 331, in _query
    self._do_get_result(db)
  File "e:\NAL-USDA\NAL_LIBRARY_SYSTEM\env\Lib\site-packages\MySQLdb\cursors.py", line 136, in _do_get_result
    self._result = result = self._get_result()
                            ^^^^^^^^^^^^^^^^^^
  File "e:\NAL-USDA\NAL_LIBRARY_SYSTEM\env\Lib\site-packages\MySQLdb\cursors.py", line 363, in _get_result
    return self._get_db().store_result()
           ^^^^^^^^^^^^^^^^^^^^^^^^^^^^^
django.db.utils.DataError: (1406, "Data too long for column 'password' at row 1")
ERROR 2024-02-22 20:44:05,761 basehttp 8512 27584 "POST /providers-ftp/ HTTP/1.1" 500 271951
ERROR 2024-02-22 20:44:39,883 log 31504 26136 Internal Server Error: /providers-ftp/
Traceback (most recent call last):
  File "e:\NAL-USDA\NAL_LIBRARY_SYSTEM\env\Lib\site-packages\django\db\backends\utils.py", line 89, in _execute
    return self.cursor.execute(sql, params)
           ^^^^^^^^^^^^^^^^^^^^^^^^^^^^^^^^
  File "e:\NAL-USDA\NAL_LIBRARY_SYSTEM\env\Lib\site-packages\django\db\backends\mysql\base.py", line 75, in execute
    return self.cursor.execute(query, args)
           ^^^^^^^^^^^^^^^^^^^^^^^^^^^^^^^^
  File "e:\NAL-USDA\NAL_LIBRARY_SYSTEM\env\Lib\site-packages\MySQLdb\cursors.py", line 179, in execute
    res = self._query(mogrified_query)
          ^^^^^^^^^^^^^^^^^^^^^^^^^^^^
  File "e:\NAL-USDA\NAL_LIBRARY_SYSTEM\env\Lib\site-packages\MySQLdb\cursors.py", line 331, in _query
    self._do_get_result(db)
  File "e:\NAL-USDA\NAL_LIBRARY_SYSTEM\env\Lib\site-packages\MySQLdb\cursors.py", line 136, in _do_get_result
    self._result = result = self._get_result()
                            ^^^^^^^^^^^^^^^^^^
  File "e:\NAL-USDA\NAL_LIBRARY_SYSTEM\env\Lib\site-packages\MySQLdb\cursors.py", line 363, in _get_result
    return self._get_db().store_result()
           ^^^^^^^^^^^^^^^^^^^^^^^^^^^^^
MySQLdb.DataError: (1406, "Data too long for column 'password' at row 1")

The above exception was the direct cause of the following exception:

Traceback (most recent call last):
  File "e:\NAL-USDA\NAL_LIBRARY_SYSTEM\env\Lib\site-packages\django\core\handlers\exception.py", line 55, in inner
    response = get_response(request)
               ^^^^^^^^^^^^^^^^^^^^^
  File "e:\NAL-USDA\NAL_LIBRARY_SYSTEM\env\Lib\site-packages\django\core\handlers\base.py", line 197, in _get_response
    response = wrapped_callback(request, *callback_args, **callback_kwargs)
               ^^^^^^^^^^^^^^^^^^^^^^^^^^^^^^^^^^^^^^^^^^^^^^^^^^^^^^^^^^^^
  File "e:\NAL-USDA\NAL_LIBRARY_SYSTEM\env\Lib\site-packages\django\views\decorators\csrf.py", line 56, in wrapper_view
    return view_func(*args, **kwargs)
           ^^^^^^^^^^^^^^^^^^^^^^^^^^
  File "e:\NAL-USDA\NAL_LIBRARY_SYSTEM\env\Lib\site-packages\rest_framework\viewsets.py", line 125, in view
    return self.dispatch(request, *args, **kwargs)
           ^^^^^^^^^^^^^^^^^^^^^^^^^^^^^^^^^^^^^^^
  File "e:\NAL-USDA\NAL_LIBRARY_SYSTEM\env\Lib\site-packages\rest_framework\views.py", line 509, in dispatch
    response = self.handle_exception(exc)
               ^^^^^^^^^^^^^^^^^^^^^^^^^^
  File "e:\NAL-USDA\NAL_LIBRARY_SYSTEM\env\Lib\site-packages\rest_framework\views.py", line 469, in handle_exception
    self.raise_uncaught_exception(exc)
  File "e:\NAL-USDA\NAL_LIBRARY_SYSTEM\env\Lib\site-packages\rest_framework\views.py", line 480, in raise_uncaught_exception
    raise exc
  File "e:\NAL-USDA\NAL_LIBRARY_SYSTEM\env\Lib\site-packages\rest_framework\views.py", line 506, in dispatch
    response = handler(request, *args, **kwargs)
               ^^^^^^^^^^^^^^^^^^^^^^^^^^^^^^^^^
  File "e:\NAL-USDA\NAL_LIBRARY_SYSTEM\env\Lib\site-packages\rest_framework\mixins.py", line 19, in create
    self.perform_create(serializer)
  File "e:\NAL-USDA\NAL_LIBRARY_SYSTEM\env\Lib\site-packages\rest_framework\mixins.py", line 24, in perform_create
    serializer.save()
  File "e:\NAL-USDA\NAL_LIBRARY_SYSTEM\env\Lib\site-packages\rest_framework\serializers.py", line 212, in save
    self.instance = self.create(validated_data)
                    ^^^^^^^^^^^^^^^^^^^^^^^^^^^
  File "e:\NAL-USDA\NAL_LIBRARY_SYSTEM\env\Lib\site-packages\rest_framework\serializers.py", line 962, in create
    instance = ModelClass._default_manager.create(**validated_data)
               ^^^^^^^^^^^^^^^^^^^^^^^^^^^^^^^^^^^^^^^^^^^^^^^^^^^^
  File "e:\NAL-USDA\NAL_LIBRARY_SYSTEM\env\Lib\site-packages\django\db\models\manager.py", line 87, in manager_method
    return getattr(self.get_queryset(), name)(*args, **kwargs)
           ^^^^^^^^^^^^^^^^^^^^^^^^^^^^^^^^^^^^^^^^^^^^^^^^^^^
  File "e:\NAL-USDA\NAL_LIBRARY_SYSTEM\env\Lib\site-packages\django\db\models\query.py", line 658, in create
    obj.save(force_insert=True, using=self.db)
  File "E:\NAL-USDA\NAL_LIBRARY_SYSTEM\actions\providers.py", line 47, in save
    super(Provider_meta_data_FTP, self).save(*args, **kwargs)
  File "e:\NAL-USDA\NAL_LIBRARY_SYSTEM\env\Lib\site-packages\django\db\models\base.py", line 814, in save
    self.save_base(
  File "e:\NAL-USDA\NAL_LIBRARY_SYSTEM\env\Lib\site-packages\django\db\models\base.py", line 877, in save_base
    updated = self._save_table(
              ^^^^^^^^^^^^^^^^^
  File "e:\NAL-USDA\NAL_LIBRARY_SYSTEM\env\Lib\site-packages\django\db\models\base.py", line 1020, in _save_table
    results = self._do_insert(
              ^^^^^^^^^^^^^^^^
  File "e:\NAL-USDA\NAL_LIBRARY_SYSTEM\env\Lib\site-packages\django\db\models\base.py", line 1061, in _do_insert
    return manager._insert(
           ^^^^^^^^^^^^^^^^
  File "e:\NAL-USDA\NAL_LIBRARY_SYSTEM\env\Lib\site-packages\django\db\models\manager.py", line 87, in manager_method
    return getattr(self.get_queryset(), name)(*args, **kwargs)
           ^^^^^^^^^^^^^^^^^^^^^^^^^^^^^^^^^^^^^^^^^^^^^^^^^^^
  File "e:\NAL-USDA\NAL_LIBRARY_SYSTEM\env\Lib\site-packages\django\db\models\query.py", line 1805, in _insert
    return query.get_compiler(using=using).execute_sql(returning_fields)
           ^^^^^^^^^^^^^^^^^^^^^^^^^^^^^^^^^^^^^^^^^^^^^^^^^^^^^^^^^^^^^
  File "e:\NAL-USDA\NAL_LIBRARY_SYSTEM\env\Lib\site-packages\django\db\models\sql\compiler.py", line 1820, in execute_sql
    cursor.execute(sql, params)
  File "e:\NAL-USDA\NAL_LIBRARY_SYSTEM\env\Lib\site-packages\django\db\backends\utils.py", line 102, in execute
    return super().execute(sql, params)
           ^^^^^^^^^^^^^^^^^^^^^^^^^^^^
  File "e:\NAL-USDA\NAL_LIBRARY_SYSTEM\env\Lib\site-packages\django\db\backends\utils.py", line 67, in execute
    return self._execute_with_wrappers(
           ^^^^^^^^^^^^^^^^^^^^^^^^^^^^
  File "e:\NAL-USDA\NAL_LIBRARY_SYSTEM\env\Lib\site-packages\django\db\backends\utils.py", line 80, in _execute_with_wrappers
    return executor(sql, params, many, context)
           ^^^^^^^^^^^^^^^^^^^^^^^^^^^^^^^^^^^^
  File "e:\NAL-USDA\NAL_LIBRARY_SYSTEM\env\Lib\site-packages\django\db\backends\utils.py", line 84, in _execute
    with self.db.wrap_database_errors:
  File "e:\NAL-USDA\NAL_LIBRARY_SYSTEM\env\Lib\site-packages\django\db\utils.py", line 91, in __exit__
    raise dj_exc_value.with_traceback(traceback) from exc_value
  File "e:\NAL-USDA\NAL_LIBRARY_SYSTEM\env\Lib\site-packages\django\db\backends\utils.py", line 89, in _execute
    return self.cursor.execute(sql, params)
           ^^^^^^^^^^^^^^^^^^^^^^^^^^^^^^^^
  File "e:\NAL-USDA\NAL_LIBRARY_SYSTEM\env\Lib\site-packages\django\db\backends\mysql\base.py", line 75, in execute
    return self.cursor.execute(query, args)
           ^^^^^^^^^^^^^^^^^^^^^^^^^^^^^^^^
  File "e:\NAL-USDA\NAL_LIBRARY_SYSTEM\env\Lib\site-packages\MySQLdb\cursors.py", line 179, in execute
    res = self._query(mogrified_query)
          ^^^^^^^^^^^^^^^^^^^^^^^^^^^^
  File "e:\NAL-USDA\NAL_LIBRARY_SYSTEM\env\Lib\site-packages\MySQLdb\cursors.py", line 331, in _query
    self._do_get_result(db)
  File "e:\NAL-USDA\NAL_LIBRARY_SYSTEM\env\Lib\site-packages\MySQLdb\cursors.py", line 136, in _do_get_result
    self._result = result = self._get_result()
                            ^^^^^^^^^^^^^^^^^^
  File "e:\NAL-USDA\NAL_LIBRARY_SYSTEM\env\Lib\site-packages\MySQLdb\cursors.py", line 363, in _get_result
    return self._get_db().store_result()
           ^^^^^^^^^^^^^^^^^^^^^^^^^^^^^
django.db.utils.DataError: (1406, "Data too long for column 'password' at row 1")
ERROR 2024-02-22 20:44:39,899 basehttp 31504 26136 "POST /providers-ftp/ HTTP/1.1" 500 271792
ERROR 2024-02-22 20:47:17,102 log 27620 25228 Internal Server Error: /providers-ftp/
Traceback (most recent call last):
  File "e:\NAL-USDA\NAL_LIBRARY_SYSTEM\env\Lib\site-packages\django\db\backends\utils.py", line 89, in _execute
    return self.cursor.execute(sql, params)
           ^^^^^^^^^^^^^^^^^^^^^^^^^^^^^^^^
  File "e:\NAL-USDA\NAL_LIBRARY_SYSTEM\env\Lib\site-packages\django\db\backends\mysql\base.py", line 75, in execute
    return self.cursor.execute(query, args)
           ^^^^^^^^^^^^^^^^^^^^^^^^^^^^^^^^
  File "e:\NAL-USDA\NAL_LIBRARY_SYSTEM\env\Lib\site-packages\MySQLdb\cursors.py", line 179, in execute
    res = self._query(mogrified_query)
          ^^^^^^^^^^^^^^^^^^^^^^^^^^^^
  File "e:\NAL-USDA\NAL_LIBRARY_SYSTEM\env\Lib\site-packages\MySQLdb\cursors.py", line 331, in _query
    self._do_get_result(db)
  File "e:\NAL-USDA\NAL_LIBRARY_SYSTEM\env\Lib\site-packages\MySQLdb\cursors.py", line 136, in _do_get_result
    self._result = result = self._get_result()
                            ^^^^^^^^^^^^^^^^^^
  File "e:\NAL-USDA\NAL_LIBRARY_SYSTEM\env\Lib\site-packages\MySQLdb\cursors.py", line 363, in _get_result
    return self._get_db().store_result()
           ^^^^^^^^^^^^^^^^^^^^^^^^^^^^^
MySQLdb.DataError: (1406, "Data too long for column 'password' at row 1")

The above exception was the direct cause of the following exception:

Traceback (most recent call last):
  File "e:\NAL-USDA\NAL_LIBRARY_SYSTEM\env\Lib\site-packages\django\core\handlers\exception.py", line 55, in inner
    response = get_response(request)
               ^^^^^^^^^^^^^^^^^^^^^
  File "e:\NAL-USDA\NAL_LIBRARY_SYSTEM\env\Lib\site-packages\django\core\handlers\base.py", line 197, in _get_response
    response = wrapped_callback(request, *callback_args, **callback_kwargs)
               ^^^^^^^^^^^^^^^^^^^^^^^^^^^^^^^^^^^^^^^^^^^^^^^^^^^^^^^^^^^^
  File "e:\NAL-USDA\NAL_LIBRARY_SYSTEM\env\Lib\site-packages\django\views\decorators\csrf.py", line 56, in wrapper_view
    return view_func(*args, **kwargs)
           ^^^^^^^^^^^^^^^^^^^^^^^^^^
  File "e:\NAL-USDA\NAL_LIBRARY_SYSTEM\env\Lib\site-packages\rest_framework\viewsets.py", line 125, in view
    return self.dispatch(request, *args, **kwargs)
           ^^^^^^^^^^^^^^^^^^^^^^^^^^^^^^^^^^^^^^^
  File "e:\NAL-USDA\NAL_LIBRARY_SYSTEM\env\Lib\site-packages\rest_framework\views.py", line 509, in dispatch
    response = self.handle_exception(exc)
               ^^^^^^^^^^^^^^^^^^^^^^^^^^
  File "e:\NAL-USDA\NAL_LIBRARY_SYSTEM\env\Lib\site-packages\rest_framework\views.py", line 469, in handle_exception
    self.raise_uncaught_exception(exc)
  File "e:\NAL-USDA\NAL_LIBRARY_SYSTEM\env\Lib\site-packages\rest_framework\views.py", line 480, in raise_uncaught_exception
    raise exc
  File "e:\NAL-USDA\NAL_LIBRARY_SYSTEM\env\Lib\site-packages\rest_framework\views.py", line 506, in dispatch
    response = handler(request, *args, **kwargs)
               ^^^^^^^^^^^^^^^^^^^^^^^^^^^^^^^^^
  File "e:\NAL-USDA\NAL_LIBRARY_SYSTEM\env\Lib\site-packages\rest_framework\mixins.py", line 19, in create
    self.perform_create(serializer)
  File "e:\NAL-USDA\NAL_LIBRARY_SYSTEM\env\Lib\site-packages\rest_framework\mixins.py", line 24, in perform_create
    serializer.save()
  File "e:\NAL-USDA\NAL_LIBRARY_SYSTEM\env\Lib\site-packages\rest_framework\serializers.py", line 212, in save
    self.instance = self.create(validated_data)
                    ^^^^^^^^^^^^^^^^^^^^^^^^^^^
  File "e:\NAL-USDA\NAL_LIBRARY_SYSTEM\env\Lib\site-packages\rest_framework\serializers.py", line 962, in create
    instance = ModelClass._default_manager.create(**validated_data)
               ^^^^^^^^^^^^^^^^^^^^^^^^^^^^^^^^^^^^^^^^^^^^^^^^^^^^
  File "e:\NAL-USDA\NAL_LIBRARY_SYSTEM\env\Lib\site-packages\django\db\models\manager.py", line 87, in manager_method
    return getattr(self.get_queryset(), name)(*args, **kwargs)
           ^^^^^^^^^^^^^^^^^^^^^^^^^^^^^^^^^^^^^^^^^^^^^^^^^^^
  File "e:\NAL-USDA\NAL_LIBRARY_SYSTEM\env\Lib\site-packages\django\db\models\query.py", line 658, in create
    obj.save(force_insert=True, using=self.db)
  File "E:\NAL-USDA\NAL_LIBRARY_SYSTEM\actions\providers.py", line 47, in save
    super(Provider_meta_data_FTP, self).save(*args, **kwargs)
  File "e:\NAL-USDA\NAL_LIBRARY_SYSTEM\env\Lib\site-packages\django\db\models\base.py", line 814, in save
    self.save_base(
  File "e:\NAL-USDA\NAL_LIBRARY_SYSTEM\env\Lib\site-packages\django\db\models\base.py", line 877, in save_base
    updated = self._save_table(
              ^^^^^^^^^^^^^^^^^
  File "e:\NAL-USDA\NAL_LIBRARY_SYSTEM\env\Lib\site-packages\django\db\models\base.py", line 1020, in _save_table
    results = self._do_insert(
              ^^^^^^^^^^^^^^^^
  File "e:\NAL-USDA\NAL_LIBRARY_SYSTEM\env\Lib\site-packages\django\db\models\base.py", line 1061, in _do_insert
    return manager._insert(
           ^^^^^^^^^^^^^^^^
  File "e:\NAL-USDA\NAL_LIBRARY_SYSTEM\env\Lib\site-packages\django\db\models\manager.py", line 87, in manager_method
    return getattr(self.get_queryset(), name)(*args, **kwargs)
           ^^^^^^^^^^^^^^^^^^^^^^^^^^^^^^^^^^^^^^^^^^^^^^^^^^^
  File "e:\NAL-USDA\NAL_LIBRARY_SYSTEM\env\Lib\site-packages\django\db\models\query.py", line 1805, in _insert
    return query.get_compiler(using=using).execute_sql(returning_fields)
           ^^^^^^^^^^^^^^^^^^^^^^^^^^^^^^^^^^^^^^^^^^^^^^^^^^^^^^^^^^^^^
  File "e:\NAL-USDA\NAL_LIBRARY_SYSTEM\env\Lib\site-packages\django\db\models\sql\compiler.py", line 1820, in execute_sql
    cursor.execute(sql, params)
  File "e:\NAL-USDA\NAL_LIBRARY_SYSTEM\env\Lib\site-packages\django\db\backends\utils.py", line 102, in execute
    return super().execute(sql, params)
           ^^^^^^^^^^^^^^^^^^^^^^^^^^^^
  File "e:\NAL-USDA\NAL_LIBRARY_SYSTEM\env\Lib\site-packages\django\db\backends\utils.py", line 67, in execute
    return self._execute_with_wrappers(
           ^^^^^^^^^^^^^^^^^^^^^^^^^^^^
  File "e:\NAL-USDA\NAL_LIBRARY_SYSTEM\env\Lib\site-packages\django\db\backends\utils.py", line 80, in _execute_with_wrappers
    return executor(sql, params, many, context)
           ^^^^^^^^^^^^^^^^^^^^^^^^^^^^^^^^^^^^
  File "e:\NAL-USDA\NAL_LIBRARY_SYSTEM\env\Lib\site-packages\django\db\backends\utils.py", line 84, in _execute
    with self.db.wrap_database_errors:
  File "e:\NAL-USDA\NAL_LIBRARY_SYSTEM\env\Lib\site-packages\django\db\utils.py", line 91, in __exit__
    raise dj_exc_value.with_traceback(traceback) from exc_value
  File "e:\NAL-USDA\NAL_LIBRARY_SYSTEM\env\Lib\site-packages\django\db\backends\utils.py", line 89, in _execute
    return self.cursor.execute(sql, params)
           ^^^^^^^^^^^^^^^^^^^^^^^^^^^^^^^^
  File "e:\NAL-USDA\NAL_LIBRARY_SYSTEM\env\Lib\site-packages\django\db\backends\mysql\base.py", line 75, in execute
    return self.cursor.execute(query, args)
           ^^^^^^^^^^^^^^^^^^^^^^^^^^^^^^^^
  File "e:\NAL-USDA\NAL_LIBRARY_SYSTEM\env\Lib\site-packages\MySQLdb\cursors.py", line 179, in execute
    res = self._query(mogrified_query)
          ^^^^^^^^^^^^^^^^^^^^^^^^^^^^
  File "e:\NAL-USDA\NAL_LIBRARY_SYSTEM\env\Lib\site-packages\MySQLdb\cursors.py", line 331, in _query
    self._do_get_result(db)
  File "e:\NAL-USDA\NAL_LIBRARY_SYSTEM\env\Lib\site-packages\MySQLdb\cursors.py", line 136, in _do_get_result
    self._result = result = self._get_result()
                            ^^^^^^^^^^^^^^^^^^
  File "e:\NAL-USDA\NAL_LIBRARY_SYSTEM\env\Lib\site-packages\MySQLdb\cursors.py", line 363, in _get_result
    return self._get_db().store_result()
           ^^^^^^^^^^^^^^^^^^^^^^^^^^^^^
django.db.utils.DataError: (1406, "Data too long for column 'password' at row 1")
ERROR 2024-02-22 20:47:17,112 basehttp 27620 25228 "POST /providers-ftp/ HTTP/1.1" 500 272711
ERROR 2024-02-22 20:51:53,306 log 25640 744 Internal Server Error: /step1/
Traceback (most recent call last):
  File "e:\NAL-USDA\NAL_LIBRARY_SYSTEM\env\Lib\site-packages\django\core\handlers\exception.py", line 55, in inner
    response = get_response(request)
               ^^^^^^^^^^^^^^^^^^^^^
  File "e:\NAL-USDA\NAL_LIBRARY_SYSTEM\env\Lib\site-packages\django\core\handlers\base.py", line 197, in _get_response
    response = wrapped_callback(request, *callback_args, **callback_kwargs)
               ^^^^^^^^^^^^^^^^^^^^^^^^^^^^^^^^^^^^^^^^^^^^^^^^^^^^^^^^^^^^
  File "e:\NAL-USDA\NAL_LIBRARY_SYSTEM\env\Lib\site-packages\django\views\decorators\csrf.py", line 56, in wrapper_view
    return view_func(*args, **kwargs)
           ^^^^^^^^^^^^^^^^^^^^^^^^^^
  File "e:\NAL-USDA\NAL_LIBRARY_SYSTEM\env\Lib\site-packages\django\views\generic\base.py", line 104, in view
    return self.dispatch(request, *args, **kwargs)
  File "c:\Users\boss\.vscode\extensions\ms-python.python-2024.0.1\pythonFiles\lib\python\debugpy\_vendored\pydevd\_pydevd_bundle\pydevd_trace_dispatch_regular.py", line 203, in trace_dispatch
    py_db.enable_tracing(thread_trace_func)
  File "c:\Users\boss\.vscode\extensions\ms-python.python-2024.0.1\pythonFiles\lib\python\debugpy\_vendored\pydevd\pydevd.py", line 1107, in enable_tracing
    pydevd_tracing.SetTrace(thread_trace_func)
  File "c:\Users\boss\.vscode\extensions\ms-python.python-2024.0.1\pythonFiles\lib\python\debugpy\_vendored\pydevd\pydevd_tracing.py", line 87, in SetTrace
    if set_trace_to_threads(tracing_func, thread_idents=[thread.get_ident()], create_dummy_thread=False) == 0:
       ^^^^^^^^^^^^^^^^^^^^^^^^^^^^^^^^^^^^^^^^^^^^^^^^^^^^^^^^^^^^^^^^^^^^^^^^^^^^^^^^^^^^^^^^^^^^^^^^^
  File "c:\Users\boss\.vscode\extensions\ms-python.python-2024.0.1\pythonFiles\lib\python\debugpy\_vendored\pydevd\pydevd_tracing.py", line 354, in set_trace_to_threads
    start_new_thread(increase_tracing_count, ())
RuntimeError: can't create new thread at interpreter shutdown
ERROR 2024-02-22 20:51:53,310 basehttp 25640 744 "GET /step1/ HTTP/1.1" 500 112493
ERROR 2024-02-22 20:52:16,600 log 27620 24652 Internal Server Error: /step1/
Traceback (most recent call last):
  File "e:\NAL-USDA\NAL_LIBRARY_SYSTEM\env\Lib\site-packages\django\core\handlers\exception.py", line 55, in inner
    response = get_response(request)
               ^^^^^^^^^^^^^^^^^^^^^
  File "e:\NAL-USDA\NAL_LIBRARY_SYSTEM\env\Lib\site-packages\django\core\handlers\base.py", line 197, in _get_response
    response = wrapped_callback(request, *callback_args, **callback_kwargs)
               ^^^^^^^^^^^^^^^^^^^^^^^^^^^^^^^^^^^^^^^^^^^^^^^^^^^^^^^^^^^^
  File "e:\NAL-USDA\NAL_LIBRARY_SYSTEM\env\Lib\site-packages\django\views\decorators\csrf.py", line 56, in wrapper_view
    return view_func(*args, **kwargs)
           ^^^^^^^^^^^^^^^^^^^^^^^^^^
  File "e:\NAL-USDA\NAL_LIBRARY_SYSTEM\env\Lib\site-packages\django\views\generic\base.py", line 104, in view
    return self.dispatch(request, *args, **kwargs)
           ^^^^^^^^^^^^^^^^^^^^^^^^^^^^^^^^^^^^^^^
  File "e:\NAL-USDA\NAL_LIBRARY_SYSTEM\env\Lib\site-packages\rest_framework\views.py", line 509, in dispatch
    response = self.handle_exception(exc)
               ^^^^^^^^^^^^^^^^^^^^^^^^^^
  File "e:\NAL-USDA\NAL_LIBRARY_SYSTEM\env\Lib\site-packages\rest_framework\views.py", line 469, in handle_exception
    self.raise_uncaught_exception(exc)
  File "e:\NAL-USDA\NAL_LIBRARY_SYSTEM\env\Lib\site-packages\rest_framework\views.py", line 480, in raise_uncaught_exception
    raise exc
  File "e:\NAL-USDA\NAL_LIBRARY_SYSTEM\env\Lib\site-packages\rest_framework\views.py", line 506, in dispatch
    response = handler(request, *args, **kwargs)
               ^^^^^^^^^^^^^^^^^^^^^^^^^^^^^^^^^
  File "e:\NAL-USDA\NAL_LIBRARY_SYSTEM\env\Lib\site-packages\rest_framework\decorators.py", line 50, in handler
    return func(*args, **kwargs)
           ^^^^^^^^^^^^^^^^^^^^^
  File "E:\NAL-USDA\NAL_LIBRARY_SYSTEM\actions\step1.py", line 33, in start_step1
    due_for_download = Provider_meta_data_FTP.objects.filter(
                       ^^^^^^^^^^^^^^^^^^^^^^^^^^^^^^^^^^^^^^
  File "e:\NAL-USDA\NAL_LIBRARY_SYSTEM\env\Lib\site-packages\django\db\models\manager.py", line 87, in manager_method
    return getattr(self.get_queryset(), name)(*args, **kwargs)
           ^^^^^^^^^^^^^^^^^^^^^^^^^^^^^^^^^^^^^^^^^^^^^^^^^^^
  File "e:\NAL-USDA\NAL_LIBRARY_SYSTEM\env\Lib\site-packages\django\db\models\query.py", line 1436, in filter
    return self._filter_or_exclude(False, args, kwargs)
           ^^^^^^^^^^^^^^^^^^^^^^^^^^^^^^^^^^^^^^^^^^^^
  File "e:\NAL-USDA\NAL_LIBRARY_SYSTEM\env\Lib\site-packages\django\db\models\query.py", line 1454, in _filter_or_exclude
    clone._filter_or_exclude_inplace(negate, args, kwargs)
  File "e:\NAL-USDA\NAL_LIBRARY_SYSTEM\env\Lib\site-packages\django\db\models\query.py", line 1461, in _filter_or_exclude_inplace
    self._query.add_q(Q(*args, **kwargs))
  File "e:\NAL-USDA\NAL_LIBRARY_SYSTEM\env\Lib\site-packages\django\db\models\sql\query.py", line 1498, in add_q
    clause, _ = self._add_q(q_object, self.used_aliases)
                ^^^^^^^^^^^^^^^^^^^^^^^^^^^^^^^^^^^^^^^^
  File "e:\NAL-USDA\NAL_LIBRARY_SYSTEM\env\Lib\site-packages\django\db\models\sql\query.py", line 1529, in _add_q
    child_clause, needed_inner = self.build_filter(
                                 ^^^^^^^^^^^^^^^^^^
  File "e:\NAL-USDA\NAL_LIBRARY_SYSTEM\env\Lib\site-packages\django\db\models\sql\query.py", line 1444, in build_filter
    condition = self.build_lookup(lookups, col, value)
                ^^^^^^^^^^^^^^^^^^^^^^^^^^^^^^^^^^^^^^
  File "e:\NAL-USDA\NAL_LIBRARY_SYSTEM\env\Lib\site-packages\django\db\models\sql\query.py", line 1271, in build_lookup
    lookup = lookup_class(lhs, rhs)
             ^^^^^^^^^^^^^^^^^^^^^^
  File "e:\NAL-USDA\NAL_LIBRARY_SYSTEM\env\Lib\site-packages\django\db\models\lookups.py", line 27, in __init__
    self.rhs = self.get_prep_lookup()
               ^^^^^^^^^^^^^^^^^^^^^^
  File "e:\NAL-USDA\NAL_LIBRARY_SYSTEM\env\Lib\site-packages\django\db\models\lookups.py", line 341, in get_prep_lookup
    return super().get_prep_lookup()
           ^^^^^^^^^^^^^^^^^^^^^^^^^
  File "e:\NAL-USDA\NAL_LIBRARY_SYSTEM\env\Lib\site-packages\django\db\models\lookups.py", line 85, in get_prep_lookup
    return self.lhs.output_field.get_prep_value(self.rhs)
           ^^^^^^^^^^^^^^^^^^^^^^^^^^^^^^^^^^^^^^^^^^^^^^
  File "e:\NAL-USDA\NAL_LIBRARY_SYSTEM\env\Lib\site-packages\django\db\models\fields\__init__.py", line 1585, in get_prep_value
    value = super().get_prep_value(value)
            ^^^^^^^^^^^^^^^^^^^^^^^^^^^^^
  File "e:\NAL-USDA\NAL_LIBRARY_SYSTEM\env\Lib\site-packages\django\db\models\fields\__init__.py", line 1464, in get_prep_value
    return self.to_python(value)
           ^^^^^^^^^^^^^^^^^^^^^
  File "e:\NAL-USDA\NAL_LIBRARY_SYSTEM\env\Lib\site-packages\django\db\models\fields\__init__.py", line 1546, in to_python
    parsed = parse_datetime(value)
             ^^^^^^^^^^^^^^^^^^^^^
  File "e:\NAL-USDA\NAL_LIBRARY_SYSTEM\env\Lib\site-packages\django\utils\dateparse.py", line 114, in parse_datetime
    return datetime.datetime.fromisoformat(value)
           ^^^^^^^^^^^^^^^^^^^^^^^^^^^^^^^^^^^^^^
TypeError: fromisoformat: argument must be str
ERROR 2024-02-22 20:52:16,623 basehttp 27620 24652 "GET /step1/ HTTP/1.1" 500 189783
ERROR 2024-02-22 21:06:09,740 log 2224 24636 Internal Server Error: /providers-ftp/
Traceback (most recent call last):
  File "e:\NAL-USDA\NAL_LIBRARY_SYSTEM\env\Lib\site-packages\django\db\backends\utils.py", line 89, in _execute
    return self.cursor.execute(sql, params)
           ^^^^^^^^^^^^^^^^^^^^^^^^^^^^^^^^
  File "e:\NAL-USDA\NAL_LIBRARY_SYSTEM\env\Lib\site-packages\django\db\backends\mysql\base.py", line 75, in execute
    return self.cursor.execute(query, args)
           ^^^^^^^^^^^^^^^^^^^^^^^^^^^^^^^^
  File "e:\NAL-USDA\NAL_LIBRARY_SYSTEM\env\Lib\site-packages\MySQLdb\cursors.py", line 179, in execute
    res = self._query(mogrified_query)
          ^^^^^^^^^^^^^^^^^^^^^^^^^^^^
  File "e:\NAL-USDA\NAL_LIBRARY_SYSTEM\env\Lib\site-packages\MySQLdb\cursors.py", line 331, in _query
    self._do_get_result(db)
  File "e:\NAL-USDA\NAL_LIBRARY_SYSTEM\env\Lib\site-packages\MySQLdb\cursors.py", line 136, in _do_get_result
    self._result = result = self._get_result()
                            ^^^^^^^^^^^^^^^^^^
  File "e:\NAL-USDA\NAL_LIBRARY_SYSTEM\env\Lib\site-packages\MySQLdb\cursors.py", line 363, in _get_result
    return self._get_db().store_result()
           ^^^^^^^^^^^^^^^^^^^^^^^^^^^^^
MySQLdb.DataError: (1406, "Data too long for column 'password' at row 1")

The above exception was the direct cause of the following exception:

Traceback (most recent call last):
  File "e:\NAL-USDA\NAL_LIBRARY_SYSTEM\env\Lib\site-packages\django\core\handlers\exception.py", line 55, in inner
    response = get_response(request)
               ^^^^^^^^^^^^^^^^^^^^^
  File "e:\NAL-USDA\NAL_LIBRARY_SYSTEM\env\Lib\site-packages\django\core\handlers\base.py", line 197, in _get_response
    response = wrapped_callback(request, *callback_args, **callback_kwargs)
               ^^^^^^^^^^^^^^^^^^^^^^^^^^^^^^^^^^^^^^^^^^^^^^^^^^^^^^^^^^^^
  File "e:\NAL-USDA\NAL_LIBRARY_SYSTEM\env\Lib\site-packages\django\views\decorators\csrf.py", line 56, in wrapper_view
    return view_func(*args, **kwargs)
           ^^^^^^^^^^^^^^^^^^^^^^^^^^
  File "e:\NAL-USDA\NAL_LIBRARY_SYSTEM\env\Lib\site-packages\rest_framework\viewsets.py", line 125, in view
    return self.dispatch(request, *args, **kwargs)
           ^^^^^^^^^^^^^^^^^^^^^^^^^^^^^^^^^^^^^^^
  File "e:\NAL-USDA\NAL_LIBRARY_SYSTEM\env\Lib\site-packages\rest_framework\views.py", line 509, in dispatch
    response = self.handle_exception(exc)
               ^^^^^^^^^^^^^^^^^^^^^^^^^^
  File "e:\NAL-USDA\NAL_LIBRARY_SYSTEM\env\Lib\site-packages\rest_framework\views.py", line 469, in handle_exception
    self.raise_uncaught_exception(exc)
  File "e:\NAL-USDA\NAL_LIBRARY_SYSTEM\env\Lib\site-packages\rest_framework\views.py", line 480, in raise_uncaught_exception
    raise exc
  File "e:\NAL-USDA\NAL_LIBRARY_SYSTEM\env\Lib\site-packages\rest_framework\views.py", line 506, in dispatch
    response = handler(request, *args, **kwargs)
               ^^^^^^^^^^^^^^^^^^^^^^^^^^^^^^^^^
  File "e:\NAL-USDA\NAL_LIBRARY_SYSTEM\env\Lib\site-packages\rest_framework\mixins.py", line 19, in create
    self.perform_create(serializer)
  File "e:\NAL-USDA\NAL_LIBRARY_SYSTEM\env\Lib\site-packages\rest_framework\mixins.py", line 24, in perform_create
    serializer.save()
  File "e:\NAL-USDA\NAL_LIBRARY_SYSTEM\env\Lib\site-packages\rest_framework\serializers.py", line 212, in save
    self.instance = self.create(validated_data)
                    ^^^^^^^^^^^^^^^^^^^^^^^^^^^
  File "e:\NAL-USDA\NAL_LIBRARY_SYSTEM\env\Lib\site-packages\rest_framework\serializers.py", line 962, in create
    instance = ModelClass._default_manager.create(**validated_data)
               ^^^^^^^^^^^^^^^^^^^^^^^^^^^^^^^^^^^^^^^^^^^^^^^^^^^^
  File "e:\NAL-USDA\NAL_LIBRARY_SYSTEM\env\Lib\site-packages\django\db\models\manager.py", line 87, in manager_method
    return getattr(self.get_queryset(), name)(*args, **kwargs)
           ^^^^^^^^^^^^^^^^^^^^^^^^^^^^^^^^^^^^^^^^^^^^^^^^^^^
  File "e:\NAL-USDA\NAL_LIBRARY_SYSTEM\env\Lib\site-packages\django\db\models\query.py", line 658, in create
    obj.save(force_insert=True, using=self.db)
  File "E:\NAL-USDA\NAL_LIBRARY_SYSTEM\actions\providers.py", line 47, in save
    #     super(Provider_meta_data_FTP, self).save(*args, **kwargs)
        ^^^^^^^^^^^^^^^^^^^^^^^^^^^^^^^^^^^^^^^^^^^^^^^^^^^^^^^^^
  File "e:\NAL-USDA\NAL_LIBRARY_SYSTEM\env\Lib\site-packages\django\db\models\base.py", line 814, in save
    self.save_base(
  File "e:\NAL-USDA\NAL_LIBRARY_SYSTEM\env\Lib\site-packages\django\db\models\base.py", line 877, in save_base
    updated = self._save_table(
              ^^^^^^^^^^^^^^^^^
  File "e:\NAL-USDA\NAL_LIBRARY_SYSTEM\env\Lib\site-packages\django\db\models\base.py", line 1020, in _save_table
    results = self._do_insert(
              ^^^^^^^^^^^^^^^^
  File "e:\NAL-USDA\NAL_LIBRARY_SYSTEM\env\Lib\site-packages\django\db\models\base.py", line 1061, in _do_insert
    return manager._insert(
           ^^^^^^^^^^^^^^^^
  File "e:\NAL-USDA\NAL_LIBRARY_SYSTEM\env\Lib\site-packages\django\db\models\manager.py", line 87, in manager_method
    return getattr(self.get_queryset(), name)(*args, **kwargs)
           ^^^^^^^^^^^^^^^^^^^^^^^^^^^^^^^^^^^^^^^^^^^^^^^^^^^
  File "e:\NAL-USDA\NAL_LIBRARY_SYSTEM\env\Lib\site-packages\django\db\models\query.py", line 1805, in _insert
    return query.get_compiler(using=using).execute_sql(returning_fields)
           ^^^^^^^^^^^^^^^^^^^^^^^^^^^^^^^^^^^^^^^^^^^^^^^^^^^^^^^^^^^^^
  File "e:\NAL-USDA\NAL_LIBRARY_SYSTEM\env\Lib\site-packages\django\db\models\sql\compiler.py", line 1820, in execute_sql
    cursor.execute(sql, params)
  File "e:\NAL-USDA\NAL_LIBRARY_SYSTEM\env\Lib\site-packages\django\db\backends\utils.py", line 102, in execute
    return super().execute(sql, params)
           ^^^^^^^^^^^^^^^^^^^^^^^^^^^^
  File "e:\NAL-USDA\NAL_LIBRARY_SYSTEM\env\Lib\site-packages\django\db\backends\utils.py", line 67, in execute
    return self._execute_with_wrappers(
           ^^^^^^^^^^^^^^^^^^^^^^^^^^^^
  File "e:\NAL-USDA\NAL_LIBRARY_SYSTEM\env\Lib\site-packages\django\db\backends\utils.py", line 80, in _execute_with_wrappers
    return executor(sql, params, many, context)
           ^^^^^^^^^^^^^^^^^^^^^^^^^^^^^^^^^^^^
  File "e:\NAL-USDA\NAL_LIBRARY_SYSTEM\env\Lib\site-packages\django\db\backends\utils.py", line 84, in _execute
    with self.db.wrap_database_errors:
  File "e:\NAL-USDA\NAL_LIBRARY_SYSTEM\env\Lib\site-packages\django\db\utils.py", line 91, in __exit__
    raise dj_exc_value.with_traceback(traceback) from exc_value
  File "e:\NAL-USDA\NAL_LIBRARY_SYSTEM\env\Lib\site-packages\django\db\backends\utils.py", line 89, in _execute
    return self.cursor.execute(sql, params)
           ^^^^^^^^^^^^^^^^^^^^^^^^^^^^^^^^
  File "e:\NAL-USDA\NAL_LIBRARY_SYSTEM\env\Lib\site-packages\django\db\backends\mysql\base.py", line 75, in execute
    return self.cursor.execute(query, args)
           ^^^^^^^^^^^^^^^^^^^^^^^^^^^^^^^^
  File "e:\NAL-USDA\NAL_LIBRARY_SYSTEM\env\Lib\site-packages\MySQLdb\cursors.py", line 179, in execute
    res = self._query(mogrified_query)
          ^^^^^^^^^^^^^^^^^^^^^^^^^^^^
  File "e:\NAL-USDA\NAL_LIBRARY_SYSTEM\env\Lib\site-packages\MySQLdb\cursors.py", line 331, in _query
    self._do_get_result(db)
  File "e:\NAL-USDA\NAL_LIBRARY_SYSTEM\env\Lib\site-packages\MySQLdb\cursors.py", line 136, in _do_get_result
    self._result = result = self._get_result()
                            ^^^^^^^^^^^^^^^^^^
  File "e:\NAL-USDA\NAL_LIBRARY_SYSTEM\env\Lib\site-packages\MySQLdb\cursors.py", line 363, in _get_result
    return self._get_db().store_result()
           ^^^^^^^^^^^^^^^^^^^^^^^^^^^^^
django.db.utils.DataError: (1406, "Data too long for column 'password' at row 1")
ERROR 2024-02-22 21:06:09,759 basehttp 2224 24636 "POST /providers-ftp/ HTTP/1.1" 500 272569
ERROR 2024-02-22 21:06:46,428 log 2224 24636 Internal Server Error: /providers-ftp/
Traceback (most recent call last):
  File "e:\NAL-USDA\NAL_LIBRARY_SYSTEM\env\Lib\site-packages\django\db\backends\utils.py", line 89, in _execute
    return self.cursor.execute(sql, params)
           ^^^^^^^^^^^^^^^^^^^^^^^^^^^^^^^^
  File "e:\NAL-USDA\NAL_LIBRARY_SYSTEM\env\Lib\site-packages\django\db\backends\mysql\base.py", line 75, in execute
    return self.cursor.execute(query, args)
           ^^^^^^^^^^^^^^^^^^^^^^^^^^^^^^^^
  File "e:\NAL-USDA\NAL_LIBRARY_SYSTEM\env\Lib\site-packages\MySQLdb\cursors.py", line 179, in execute
    res = self._query(mogrified_query)
          ^^^^^^^^^^^^^^^^^^^^^^^^^^^^
  File "e:\NAL-USDA\NAL_LIBRARY_SYSTEM\env\Lib\site-packages\MySQLdb\cursors.py", line 331, in _query
    self._do_get_result(db)
  File "e:\NAL-USDA\NAL_LIBRARY_SYSTEM\env\Lib\site-packages\MySQLdb\cursors.py", line 136, in _do_get_result
    self._result = result = self._get_result()
                            ^^^^^^^^^^^^^^^^^^
  File "e:\NAL-USDA\NAL_LIBRARY_SYSTEM\env\Lib\site-packages\MySQLdb\cursors.py", line 363, in _get_result
    return self._get_db().store_result()
           ^^^^^^^^^^^^^^^^^^^^^^^^^^^^^
MySQLdb.DataError: (1406, "Data too long for column 'password' at row 1")

The above exception was the direct cause of the following exception:

Traceback (most recent call last):
  File "e:\NAL-USDA\NAL_LIBRARY_SYSTEM\env\Lib\site-packages\django\core\handlers\exception.py", line 55, in inner
    response = get_response(request)
               ^^^^^^^^^^^^^^^^^^^^^
  File "e:\NAL-USDA\NAL_LIBRARY_SYSTEM\env\Lib\site-packages\django\core\handlers\base.py", line 197, in _get_response
    response = wrapped_callback(request, *callback_args, **callback_kwargs)
               ^^^^^^^^^^^^^^^^^^^^^^^^^^^^^^^^^^^^^^^^^^^^^^^^^^^^^^^^^^^^
  File "e:\NAL-USDA\NAL_LIBRARY_SYSTEM\env\Lib\site-packages\django\views\decorators\csrf.py", line 56, in wrapper_view
    return view_func(*args, **kwargs)
           ^^^^^^^^^^^^^^^^^^^^^^^^^^
  File "e:\NAL-USDA\NAL_LIBRARY_SYSTEM\env\Lib\site-packages\rest_framework\viewsets.py", line 125, in view
    return self.dispatch(request, *args, **kwargs)
           ^^^^^^^^^^^^^^^^^^^^^^^^^^^^^^^^^^^^^^^
  File "e:\NAL-USDA\NAL_LIBRARY_SYSTEM\env\Lib\site-packages\rest_framework\views.py", line 509, in dispatch
    response = self.handle_exception(exc)
               ^^^^^^^^^^^^^^^^^^^^^^^^^^
  File "e:\NAL-USDA\NAL_LIBRARY_SYSTEM\env\Lib\site-packages\rest_framework\views.py", line 469, in handle_exception
    self.raise_uncaught_exception(exc)
  File "e:\NAL-USDA\NAL_LIBRARY_SYSTEM\env\Lib\site-packages\rest_framework\views.py", line 480, in raise_uncaught_exception
    raise exc
  File "e:\NAL-USDA\NAL_LIBRARY_SYSTEM\env\Lib\site-packages\rest_framework\views.py", line 506, in dispatch
    response = handler(request, *args, **kwargs)
               ^^^^^^^^^^^^^^^^^^^^^^^^^^^^^^^^^
  File "e:\NAL-USDA\NAL_LIBRARY_SYSTEM\env\Lib\site-packages\rest_framework\mixins.py", line 19, in create
    self.perform_create(serializer)
  File "e:\NAL-USDA\NAL_LIBRARY_SYSTEM\env\Lib\site-packages\rest_framework\mixins.py", line 24, in perform_create
    serializer.save()
  File "e:\NAL-USDA\NAL_LIBRARY_SYSTEM\env\Lib\site-packages\rest_framework\serializers.py", line 212, in save
    self.instance = self.create(validated_data)
                    ^^^^^^^^^^^^^^^^^^^^^^^^^^^
  File "e:\NAL-USDA\NAL_LIBRARY_SYSTEM\env\Lib\site-packages\rest_framework\serializers.py", line 962, in create
    instance = ModelClass._default_manager.create(**validated_data)
               ^^^^^^^^^^^^^^^^^^^^^^^^^^^^^^^^^^^^^^^^^^^^^^^^^^^^
  File "e:\NAL-USDA\NAL_LIBRARY_SYSTEM\env\Lib\site-packages\django\db\models\manager.py", line 87, in manager_method
    return getattr(self.get_queryset(), name)(*args, **kwargs)
           ^^^^^^^^^^^^^^^^^^^^^^^^^^^^^^^^^^^^^^^^^^^^^^^^^^^
  File "e:\NAL-USDA\NAL_LIBRARY_SYSTEM\env\Lib\site-packages\django\db\models\query.py", line 658, in create
    obj.save(force_insert=True, using=self.db)
  File "E:\NAL-USDA\NAL_LIBRARY_SYSTEM\actions\providers.py", line 47, in save
    #     super(Provider_meta_data_FTP, self).save(*args, **kwargs)
        ^^^^^^^^^^^^^^^^^^^^^^^^^^^^^^^^^^^^^^^^^^^^^^^^^^^^^^^^^
  File "e:\NAL-USDA\NAL_LIBRARY_SYSTEM\env\Lib\site-packages\django\db\models\base.py", line 814, in save
    self.save_base(
  File "e:\NAL-USDA\NAL_LIBRARY_SYSTEM\env\Lib\site-packages\django\db\models\base.py", line 877, in save_base
    updated = self._save_table(
              ^^^^^^^^^^^^^^^^^
  File "e:\NAL-USDA\NAL_LIBRARY_SYSTEM\env\Lib\site-packages\django\db\models\base.py", line 1020, in _save_table
    results = self._do_insert(
              ^^^^^^^^^^^^^^^^
  File "e:\NAL-USDA\NAL_LIBRARY_SYSTEM\env\Lib\site-packages\django\db\models\base.py", line 1061, in _do_insert
    return manager._insert(
           ^^^^^^^^^^^^^^^^
  File "e:\NAL-USDA\NAL_LIBRARY_SYSTEM\env\Lib\site-packages\django\db\models\manager.py", line 87, in manager_method
    return getattr(self.get_queryset(), name)(*args, **kwargs)
           ^^^^^^^^^^^^^^^^^^^^^^^^^^^^^^^^^^^^^^^^^^^^^^^^^^^
  File "e:\NAL-USDA\NAL_LIBRARY_SYSTEM\env\Lib\site-packages\django\db\models\query.py", line 1805, in _insert
    return query.get_compiler(using=using).execute_sql(returning_fields)
           ^^^^^^^^^^^^^^^^^^^^^^^^^^^^^^^^^^^^^^^^^^^^^^^^^^^^^^^^^^^^^
  File "e:\NAL-USDA\NAL_LIBRARY_SYSTEM\env\Lib\site-packages\django\db\models\sql\compiler.py", line 1820, in execute_sql
    cursor.execute(sql, params)
  File "e:\NAL-USDA\NAL_LIBRARY_SYSTEM\env\Lib\site-packages\django\db\backends\utils.py", line 102, in execute
    return super().execute(sql, params)
           ^^^^^^^^^^^^^^^^^^^^^^^^^^^^
  File "e:\NAL-USDA\NAL_LIBRARY_SYSTEM\env\Lib\site-packages\django\db\backends\utils.py", line 67, in execute
    return self._execute_with_wrappers(
           ^^^^^^^^^^^^^^^^^^^^^^^^^^^^
  File "e:\NAL-USDA\NAL_LIBRARY_SYSTEM\env\Lib\site-packages\django\db\backends\utils.py", line 80, in _execute_with_wrappers
    return executor(sql, params, many, context)
           ^^^^^^^^^^^^^^^^^^^^^^^^^^^^^^^^^^^^
  File "e:\NAL-USDA\NAL_LIBRARY_SYSTEM\env\Lib\site-packages\django\db\backends\utils.py", line 84, in _execute
    with self.db.wrap_database_errors:
  File "e:\NAL-USDA\NAL_LIBRARY_SYSTEM\env\Lib\site-packages\django\db\utils.py", line 91, in __exit__
    raise dj_exc_value.with_traceback(traceback) from exc_value
  File "e:\NAL-USDA\NAL_LIBRARY_SYSTEM\env\Lib\site-packages\django\db\backends\utils.py", line 89, in _execute
    return self.cursor.execute(sql, params)
           ^^^^^^^^^^^^^^^^^^^^^^^^^^^^^^^^
  File "e:\NAL-USDA\NAL_LIBRARY_SYSTEM\env\Lib\site-packages\django\db\backends\mysql\base.py", line 75, in execute
    return self.cursor.execute(query, args)
           ^^^^^^^^^^^^^^^^^^^^^^^^^^^^^^^^
  File "e:\NAL-USDA\NAL_LIBRARY_SYSTEM\env\Lib\site-packages\MySQLdb\cursors.py", line 179, in execute
    res = self._query(mogrified_query)
          ^^^^^^^^^^^^^^^^^^^^^^^^^^^^
  File "e:\NAL-USDA\NAL_LIBRARY_SYSTEM\env\Lib\site-packages\MySQLdb\cursors.py", line 331, in _query
    self._do_get_result(db)
  File "e:\NAL-USDA\NAL_LIBRARY_SYSTEM\env\Lib\site-packages\MySQLdb\cursors.py", line 136, in _do_get_result
    self._result = result = self._get_result()
                            ^^^^^^^^^^^^^^^^^^
  File "e:\NAL-USDA\NAL_LIBRARY_SYSTEM\env\Lib\site-packages\MySQLdb\cursors.py", line 363, in _get_result
    return self._get_db().store_result()
           ^^^^^^^^^^^^^^^^^^^^^^^^^^^^^
django.db.utils.DataError: (1406, "Data too long for column 'password' at row 1")
ERROR 2024-02-22 21:06:46,433 basehttp 2224 24636 "POST /providers-ftp/ HTTP/1.1" 500 271909
ERROR 2024-02-22 21:08:20,375 log 2224 9516 Internal Server Error: /step1/
Traceback (most recent call last):
  File "e:\NAL-USDA\NAL_LIBRARY_SYSTEM\env\Lib\site-packages\django\core\handlers\exception.py", line 55, in inner
    response = get_response(request)
               ^^^^^^^^^^^^^^^^^^^^^
  File "e:\NAL-USDA\NAL_LIBRARY_SYSTEM\env\Lib\site-packages\django\core\handlers\base.py", line 197, in _get_response
    response = wrapped_callback(request, *callback_args, **callback_kwargs)
               ^^^^^^^^^^^^^^^^^^^^^^^^^^^^^^^^^^^^^^^^^^^^^^^^^^^^^^^^^^^^
  File "c:\Users\boss\.vscode\extensions\ms-python.python-2024.0.1\pythonFiles\lib\python\debugpy\_vendored\pydevd\_pydevd_bundle\pydevd_trace_dispatch_regular.py", line 203, in trace_dispatch
    py_db.enable_tracing(thread_trace_func)
  File "c:\Users\boss\.vscode\extensions\ms-python.python-2024.0.1\pythonFiles\lib\python\debugpy\_vendored\pydevd\pydevd.py", line 1107, in enable_tracing
    pydevd_tracing.SetTrace(thread_trace_func)
  File "c:\Users\boss\.vscode\extensions\ms-python.python-2024.0.1\pythonFiles\lib\python\debugpy\_vendored\pydevd\pydevd_tracing.py", line 87, in SetTrace
    if set_trace_to_threads(tracing_func, thread_idents=[thread.get_ident()], create_dummy_thread=False) == 0:
       ^^^^^^^^^^^^^^^^^^^^^^^^^^^^^^^^^^^^^^^^^^^^^^^^^^^^^^^^^^^^^^^^^^^^^^^^^^^^^^^^^^^^^^^^^^^^^^^^^
  File "c:\Users\boss\.vscode\extensions\ms-python.python-2024.0.1\pythonFiles\lib\python\debugpy\_vendored\pydevd\pydevd_tracing.py", line 354, in set_trace_to_threads
    start_new_thread(increase_tracing_count, ())
RuntimeError: can't create new thread at interpreter shutdown
ERROR 2024-02-22 21:08:20,379 basehttp 2224 9516 "GET /step1/ HTTP/1.1" 500 104224
ERROR 2024-02-22 21:19:52,818 log 11108 21856 Internal Server Error: /step1/
Traceback (most recent call last):
  File "E:\NAL-USDA\NAL_LIBRARY_SYSTEM\actions\step1.py", line 49, in start_step1
    x = connect.retrbinary(f"RETR {article}", file.write)
        ^^^^^^^^^^^^^^^^^^^^^^^^^^^^^^^^^^^^^^^^^^^^^^^^^
  File "C:\Users\boss\AppData\Local\Programs\Python\Python312\Lib\ftplib.py", line 435, in retrbinary
    self.voidcmd('TYPE I')
  File "C:\Users\boss\AppData\Local\Programs\Python\Python312\Lib\ftplib.py", line 286, in voidcmd
    return self.voidresp()
           ^^^^^^^^^^^^^^^
  File "C:\Users\boss\AppData\Local\Programs\Python\Python312\Lib\ftplib.py", line 259, in voidresp
    resp = self.getresp()
           ^^^^^^^^^^^^^^
  File "C:\Users\boss\AppData\Local\Programs\Python\Python312\Lib\ftplib.py", line 252, in getresp
    raise error_temp(resp)
ftplib.error_temp: 421 Timeout.

During handling of the above exception, another exception occurred:

Traceback (most recent call last):
  File "e:\NAL-USDA\NAL_LIBRARY_SYSTEM\env\Lib\site-packages\django\core\handlers\exception.py", line 55, in inner
    response = get_response(request)
               ^^^^^^^^^^^^^^^^^^^^^
  File "e:\NAL-USDA\NAL_LIBRARY_SYSTEM\env\Lib\site-packages\django\core\handlers\base.py", line 197, in _get_response
    response = wrapped_callback(request, *callback_args, **callback_kwargs)
               ^^^^^^^^^^^^^^^^^^^^^^^^^^^^^^^^^^^^^^^^^^^^^^^^^^^^^^^^^^^^
  File "e:\NAL-USDA\NAL_LIBRARY_SYSTEM\env\Lib\site-packages\django\views\decorators\csrf.py", line 56, in wrapper_view
    return view_func(*args, **kwargs)
           ^^^^^^^^^^^^^^^^^^^^^^^^^^
  File "e:\NAL-USDA\NAL_LIBRARY_SYSTEM\env\Lib\site-packages\django\views\generic\base.py", line 104, in view
    return self.dispatch(request, *args, **kwargs)
           ^^^^^^^^^^^^^^^^^^^^^^^^^^^^^^^^^^^^^^^
  File "e:\NAL-USDA\NAL_LIBRARY_SYSTEM\env\Lib\site-packages\rest_framework\views.py", line 509, in dispatch
    response = self.handle_exception(exc)
               ^^^^^^^^^^^^^^^^^^^^^^^^^^
  File "e:\NAL-USDA\NAL_LIBRARY_SYSTEM\env\Lib\site-packages\rest_framework\views.py", line 469, in handle_exception
    self.raise_uncaught_exception(exc)
  File "e:\NAL-USDA\NAL_LIBRARY_SYSTEM\env\Lib\site-packages\rest_framework\views.py", line 480, in raise_uncaught_exception
    raise exc
  File "e:\NAL-USDA\NAL_LIBRARY_SYSTEM\env\Lib\site-packages\rest_framework\views.py", line 506, in dispatch
    response = handler(request, *args, **kwargs)
               ^^^^^^^^^^^^^^^^^^^^^^^^^^^^^^^^^
  File "e:\NAL-USDA\NAL_LIBRARY_SYSTEM\env\Lib\site-packages\rest_framework\decorators.py", line 50, in handler
    return func(*args, **kwargs)
           ^^^^^^^^^^^^^^^^^^^^^
  File "E:\NAL-USDA\NAL_LIBRARY_SYSTEM\actions\step1.py", line 63, in start_step1
    provider = item.provider_address,
               ^^^^^^^^^^^^^^^^^^^^^
AttributeError: 'Provider_meta_data_FTP' object has no attribute 'provider_address'
ERROR 2024-02-22 21:19:52,844 basehttp 11108 21856 "GET /step1/ HTTP/1.1" 500 143689
ERROR 2024-02-22 21:22:32,698 log 11108 24832 Internal Server Error: /step1/
Traceback (most recent call last):
  File "E:\NAL-USDA\NAL_LIBRARY_SYSTEM\actions\step1.py", line 49, in start_step1
    x = connect.retrbinary(f"RETR {article}", file.write)
        ^^^^^^^^^^^^^^^^^^^^^^^^^^^^^^^^^^^^^^^^^^^^^^^^^
  File "C:\Users\boss\AppData\Local\Programs\Python\Python312\Lib\ftplib.py", line 436, in retrbinary
    with self.transfercmd(cmd, rest) as conn:
         ^^^^^^^^^^^^^^^^^^^^^^^^^^^
  File "C:\Users\boss\AppData\Local\Programs\Python\Python312\Lib\ftplib.py", line 393, in transfercmd
    return self.ntransfercmd(cmd, rest)[0]
           ^^^^^^^^^^^^^^^^^^^^^^^^^^^^
  File "C:\Users\boss\AppData\Local\Programs\Python\Python312\Lib\ftplib.py", line 359, in ntransfercmd
    resp = self.sendcmd(cmd)
           ^^^^^^^^^^^^^^^^^
  File "C:\Users\boss\AppData\Local\Programs\Python\Python312\Lib\ftplib.py", line 281, in sendcmd
    return self.getresp()
           ^^^^^^^^^^^^^^
  File "C:\Users\boss\AppData\Local\Programs\Python\Python312\Lib\ftplib.py", line 254, in getresp
    raise error_perm(resp)
ftplib.error_perm: 550 Failed to open file.

During handling of the above exception, another exception occurred:

Traceback (most recent call last):
  File "e:\NAL-USDA\NAL_LIBRARY_SYSTEM\env\Lib\site-packages\django\core\handlers\exception.py", line 55, in inner
    response = get_response(request)
               ^^^^^^^^^^^^^^^^^^^^^
  File "e:\NAL-USDA\NAL_LIBRARY_SYSTEM\env\Lib\site-packages\django\core\handlers\base.py", line 197, in _get_response
    response = wrapped_callback(request, *callback_args, **callback_kwargs)
               ^^^^^^^^^^^^^^^^^^^^^^^^^^^^^^^^^^^^^^^^^^^^^^^^^^^^^^^^^^^^
  File "e:\NAL-USDA\NAL_LIBRARY_SYSTEM\env\Lib\site-packages\django\views\decorators\csrf.py", line 56, in wrapper_view
    return view_func(*args, **kwargs)
           ^^^^^^^^^^^^^^^^^^^^^^^^^^
  File "e:\NAL-USDA\NAL_LIBRARY_SYSTEM\env\Lib\site-packages\django\views\generic\base.py", line 104, in view
    return self.dispatch(request, *args, **kwargs)
           ^^^^^^^^^^^^^^^^^^^^^^^^^^^^^^^^^^^^^^^
  File "e:\NAL-USDA\NAL_LIBRARY_SYSTEM\env\Lib\site-packages\rest_framework\views.py", line 509, in dispatch
    response = self.handle_exception(exc)
               ^^^^^^^^^^^^^^^^^^^^^^^^^^
  File "e:\NAL-USDA\NAL_LIBRARY_SYSTEM\env\Lib\site-packages\rest_framework\views.py", line 469, in handle_exception
    self.raise_uncaught_exception(exc)
  File "e:\NAL-USDA\NAL_LIBRARY_SYSTEM\env\Lib\site-packages\rest_framework\views.py", line 480, in raise_uncaught_exception
    raise exc
  File "e:\NAL-USDA\NAL_LIBRARY_SYSTEM\env\Lib\site-packages\rest_framework\views.py", line 506, in dispatch
    response = handler(request, *args, **kwargs)
               ^^^^^^^^^^^^^^^^^^^^^^^^^^^^^^^^^
  File "e:\NAL-USDA\NAL_LIBRARY_SYSTEM\env\Lib\site-packages\rest_framework\decorators.py", line 50, in handler
    return func(*args, **kwargs)
           ^^^^^^^^^^^^^^^^^^^^^
  File "E:\NAL-USDA\NAL_LIBRARY_SYSTEM\actions\step1.py", line 63, in start_step1
    provider = item.provider_address,
               ^^^^^^^^^^^^^^^^^^^^^
AttributeError: 'Provider_meta_data_FTP' object has no attribute 'provider_address'
ERROR 2024-02-22 21:22:32,733 basehttp 11108 24832 "GET /step1/ HTTP/1.1" 500 149094
ERROR 2024-02-22 21:24:59,180 basehttp 26460 29720 "GET /step1/ HTTP/1.1" 500 150880
ERROR 2024-02-22 21:28:29,105 log 26460 18948 Internal Server Error: /step1/
Traceback (most recent call last):
  File "E:\NAL-USDA\NAL_LIBRARY_SYSTEM\actions\step1.py", line 53, in start_step1
    provider = item.provider_address,
               ^^^^^^^^^^^^^^^^^^^^^
AttributeError: 'Provider_meta_data_FTP' object has no attribute 'provider_address'

During handling of the above exception, another exception occurred:

Traceback (most recent call last):
  File "e:\NAL-USDA\NAL_LIBRARY_SYSTEM\env\Lib\site-packages\django\core\handlers\exception.py", line 55, in inner
    response = get_response(request)
               ^^^^^^^^^^^^^^^^^^^^^
  File "e:\NAL-USDA\NAL_LIBRARY_SYSTEM\env\Lib\site-packages\django\core\handlers\base.py", line 197, in _get_response
    response = wrapped_callback(request, *callback_args, **callback_kwargs)
               ^^^^^^^^^^^^^^^^^^^^^^^^^^^^^^^^^^^^^^^^^^^^^^^^^^^^^^^^^^^^
  File "e:\NAL-USDA\NAL_LIBRARY_SYSTEM\env\Lib\site-packages\django\views\decorators\csrf.py", line 56, in wrapper_view
    return view_func(*args, **kwargs)
           ^^^^^^^^^^^^^^^^^^^^^^^^^^
  File "e:\NAL-USDA\NAL_LIBRARY_SYSTEM\env\Lib\site-packages\django\views\generic\base.py", line 104, in view
    return self.dispatch(request, *args, **kwargs)
           ^^^^^^^^^^^^^^^^^^^^^^^^^^^^^^^^^^^^^^^
  File "e:\NAL-USDA\NAL_LIBRARY_SYSTEM\env\Lib\site-packages\rest_framework\views.py", line 509, in dispatch
    response = self.handle_exception(exc)
               ^^^^^^^^^^^^^^^^^^^^^^^^^^
  File "e:\NAL-USDA\NAL_LIBRARY_SYSTEM\env\Lib\site-packages\rest_framework\views.py", line 469, in handle_exception
    self.raise_uncaught_exception(exc)
  File "e:\NAL-USDA\NAL_LIBRARY_SYSTEM\env\Lib\site-packages\rest_framework\views.py", line 480, in raise_uncaught_exception
    raise exc
  File "e:\NAL-USDA\NAL_LIBRARY_SYSTEM\env\Lib\site-packages\rest_framework\views.py", line 506, in dispatch
    response = handler(request, *args, **kwargs)
               ^^^^^^^^^^^^^^^^^^^^^^^^^^^^^^^^^
  File "e:\NAL-USDA\NAL_LIBRARY_SYSTEM\env\Lib\site-packages\rest_framework\decorators.py", line 50, in handler
    return func(*args, **kwargs)
           ^^^^^^^^^^^^^^^^^^^^^
  File "E:\NAL-USDA\NAL_LIBRARY_SYSTEM\actions\step1.py", line 65, in start_step1
    provider = item.provider_address,
               ^^^^^^^^^^^^^^^^^^^^^
AttributeError: 'Provider_meta_data_FTP' object has no attribute 'provider_address'
ERROR 2024-02-22 21:28:29,137 basehttp 26460 18948 "GET /step1/ HTTP/1.1" 500 127866
ERROR 2024-02-22 21:31:08,278 basehttp 26460 28988 "GET /step1/ HTTP/1.1" 500 127894
ERROR 2024-02-22 21:31:42,507 basehttp 2492 18272 "GET /step1/ HTTP/1.1" 500 127978
ERROR 2024-02-22 21:34:06,479 basehttp 32600 13592 "GET /step1/ HTTP/1.1" 500 127888
