ERROR 2024-05-03 21:06:48,465 log 33436 32932 Internal Server Error: /step2/test-xml/
Traceback (most recent call last):
  File "E:\NAL-USDA\NAL_LIBRARY_SYSTEM\step2\article.py", line 133, in read_json_file
    return xmltodict.parse(xml_txt, encoding='utf-8')
  File "e:\NAL-USDA\NAL_LIBRARY_SYSTEM\env\lib\site-packages\xmltodict.py", line 378, in parse
    parser.Parse(xml_input, True)
xml.parsers.expat.ExpatError: not well-formed (invalid token): line 29, column 487

During handling of the above exception, another exception occurred:

Traceback (most recent call last):
  File "e:\NAL-USDA\NAL_LIBRARY_SYSTEM\env\lib\site-packages\django\core\handlers\exception.py", line 55, in inner
    response = get_response(request)
  File "e:\NAL-USDA\NAL_LIBRARY_SYSTEM\env\lib\site-packages\django\core\handlers\base.py", line 197, in _get_response
    response = wrapped_callback(request, *callback_args, **callback_kwargs)
  File "e:\NAL-USDA\NAL_LIBRARY_SYSTEM\env\lib\site-packages\django\views\decorators\csrf.py", line 56, in wrapper_view
    return view_func(*args, **kwargs)
  File "e:\NAL-USDA\NAL_LIBRARY_SYSTEM\env\lib\site-packages\django\views\generic\base.py", line 104, in view
    return self.dispatch(request, *args, **kwargs)
  File "e:\NAL-USDA\NAL_LIBRARY_SYSTEM\env\lib\site-packages\rest_framework\views.py", line 509, in dispatch
    response = self.handle_exception(exc)
  File "e:\NAL-USDA\NAL_LIBRARY_SYSTEM\env\lib\site-packages\rest_framework\views.py", line 469, in handle_exception
    self.raise_uncaught_exception(exc)
  File "e:\NAL-USDA\NAL_LIBRARY_SYSTEM\env\lib\site-packages\rest_framework\views.py", line 480, in raise_uncaught_exception
    raise exc
  File "e:\NAL-USDA\NAL_LIBRARY_SYSTEM\env\lib\site-packages\rest_framework\views.py", line 506, in dispatch
    response = handler(request, *args, **kwargs)
  File "e:\NAL-USDA\NAL_LIBRARY_SYSTEM\env\lib\site-packages\rest_framework\decorators.py", line 50, in handler
    return func(*args, **kwargs)
  File "E:\NAL-USDA\NAL_LIBRARY_SYSTEM\step2\article.py", line 562, in test_xml
    is_article_tag_available(path)
  File "E:\NAL-USDA\NAL_LIBRARY_SYSTEM\step2\article.py", line 150, in is_article_tag_available
    doc = read_json_file(xml_file_path)
  File "E:\NAL-USDA\NAL_LIBRARY_SYSTEM\step2\article.py", line 137, in read_json_file
    shutil.copy(xml_file_path, destination)
  File "C:\Users\prasenjit\AppData\Local\Programs\Python\Python310\lib\shutil.py", line 417, in copy
    copyfile(src, dst, follow_symlinks=follow_symlinks)
  File "C:\Users\prasenjit\AppData\Local\Programs\Python\Python310\lib\shutil.py", line 234, in copyfile
    raise SameFileError("{!r} and {!r} are the same file".format(src, dst))
shutil.SameFileError: 'E:/NAL-USDA/NAL_LIBRARY_SYSTEM/INVALID_XML_FILES/AN17032_COabs.xml' and 'E:\\NAL-USDA\\NAL_LIBRARY_SYSTEM\\INVALID_XML_FILES\\AN17032_COabs.xml' are the same file
ERROR 2024-05-03 21:06:48,480 basehttp 33436 32932 "GET /step2/test-xml/ HTTP/1.1" 500 141616
ERROR 2024-05-03 21:09:34,848 log 33780 6104 Internal Server Error: /step2/test-xml/
Traceback (most recent call last):
  File "E:\NAL-USDA\NAL_LIBRARY_SYSTEM\step2\article.py", line 133, in read_json_file
    return xmltodict.parse(xml_txt, encoding='utf-8')
  File "e:\NAL-USDA\NAL_LIBRARY_SYSTEM\env\lib\site-packages\xmltodict.py", line 378, in parse
    parser.Parse(xml_input, True)
xml.parsers.expat.ExpatError: not well-formed (invalid token): line 29, column 487

During handling of the above exception, another exception occurred:

Traceback (most recent call last):
  File "e:\NAL-USDA\NAL_LIBRARY_SYSTEM\env\lib\site-packages\django\core\handlers\exception.py", line 55, in inner
    response = get_response(request)
  File "e:\NAL-USDA\NAL_LIBRARY_SYSTEM\env\lib\site-packages\django\core\handlers\base.py", line 197, in _get_response
    response = wrapped_callback(request, *callback_args, **callback_kwargs)
  File "e:\NAL-USDA\NAL_LIBRARY_SYSTEM\env\lib\site-packages\django\views\decorators\csrf.py", line 56, in wrapper_view
    return view_func(*args, **kwargs)
  File "e:\NAL-USDA\NAL_LIBRARY_SYSTEM\env\lib\site-packages\django\views\generic\base.py", line 104, in view
    return self.dispatch(request, *args, **kwargs)
  File "e:\NAL-USDA\NAL_LIBRARY_SYSTEM\env\lib\site-packages\rest_framework\views.py", line 509, in dispatch
    response = self.handle_exception(exc)
  File "e:\NAL-USDA\NAL_LIBRARY_SYSTEM\env\lib\site-packages\rest_framework\views.py", line 469, in handle_exception
    self.raise_uncaught_exception(exc)
  File "e:\NAL-USDA\NAL_LIBRARY_SYSTEM\env\lib\site-packages\rest_framework\views.py", line 480, in raise_uncaught_exception
    raise exc
  File "e:\NAL-USDA\NAL_LIBRARY_SYSTEM\env\lib\site-packages\rest_framework\views.py", line 506, in dispatch
    response = handler(request, *args, **kwargs)
  File "e:\NAL-USDA\NAL_LIBRARY_SYSTEM\env\lib\site-packages\rest_framework\decorators.py", line 50, in handler
    return func(*args, **kwargs)
  File "E:\NAL-USDA\NAL_LIBRARY_SYSTEM\step2\article.py", line 562, in test_xml
    is_article_tag_available(path)
  File "E:\NAL-USDA\NAL_LIBRARY_SYSTEM\step2\article.py", line 150, in is_article_tag_available
    doc = read_json_file(xml_file_path)
  File "E:\NAL-USDA\NAL_LIBRARY_SYSTEM\step2\article.py", line 137, in read_json_file
    shutil.copy(xml_file_path, destination)
  File "C:\Users\prasenjit\AppData\Local\Programs\Python\Python310\lib\shutil.py", line 417, in copy
    copyfile(src, dst, follow_symlinks=follow_symlinks)
  File "C:\Users\prasenjit\AppData\Local\Programs\Python\Python310\lib\shutil.py", line 234, in copyfile
    raise SameFileError("{!r} and {!r} are the same file".format(src, dst))
shutil.SameFileError: 'E:\\NAL-USDA\\NAL_LIBRARY_SYSTEM\\INVALID_XML_FILES\\AN17032_COabs.xml' and 'E:\\NAL-USDA\\NAL_LIBRARY_SYSTEM\\INVALID_XML_FILES\\AN17032_COabs.xml' are the same file
ERROR 2024-05-03 21:09:34,864 basehttp 33780 6104 "GET /step2/test-xml/ HTTP/1.1" 500 142080
ERROR 2024-05-03 21:29:18,113 log 21256 12728 Internal Server Error: /step2/test-xml/
Traceback (most recent call last):
  File "E:\NAL-USDA\NAL_LIBRARY_SYSTEM\step2\article.py", line 124, in read_json_file
    with open(file=xml_file_path, mode='rb') as xml_txt:
FileNotFoundError: [Errno 2] No such file or directory: 'E:\\NAL-USDA\\NAL_LIBRARY_SYSTEM\\INVALID_XML_FILES\\AN17032_COabs.xml'

During handling of the above exception, another exception occurred:

Traceback (most recent call last):
  File "e:\NAL-USDA\NAL_LIBRARY_SYSTEM\env\lib\site-packages\django\core\handlers\exception.py", line 55, in inner
    response = get_response(request)
  File "e:\NAL-USDA\NAL_LIBRARY_SYSTEM\env\lib\site-packages\django\core\handlers\base.py", line 197, in _get_response
    response = wrapped_callback(request, *callback_args, **callback_kwargs)
  File "e:\NAL-USDA\NAL_LIBRARY_SYSTEM\env\lib\site-packages\django\views\decorators\csrf.py", line 56, in wrapper_view
    return view_func(*args, **kwargs)
  File "e:\NAL-USDA\NAL_LIBRARY_SYSTEM\env\lib\site-packages\django\views\generic\base.py", line 104, in view
    return self.dispatch(request, *args, **kwargs)
  File "e:\NAL-USDA\NAL_LIBRARY_SYSTEM\env\lib\site-packages\rest_framework\views.py", line 509, in dispatch
    response = self.handle_exception(exc)
  File "e:\NAL-USDA\NAL_LIBRARY_SYSTEM\env\lib\site-packages\rest_framework\views.py", line 469, in handle_exception
    self.raise_uncaught_exception(exc)
  File "e:\NAL-USDA\NAL_LIBRARY_SYSTEM\env\lib\site-packages\rest_framework\views.py", line 480, in raise_uncaught_exception
    raise exc
  File "e:\NAL-USDA\NAL_LIBRARY_SYSTEM\env\lib\site-packages\rest_framework\views.py", line 506, in dispatch
    response = handler(request, *args, **kwargs)
  File "e:\NAL-USDA\NAL_LIBRARY_SYSTEM\env\lib\site-packages\rest_framework\decorators.py", line 50, in handler
    return func(*args, **kwargs)
  File "E:\NAL-USDA\NAL_LIBRARY_SYSTEM\step2\article.py", line 566, in test_xml
    is_article_tag_available(path)
  File "E:\NAL-USDA\NAL_LIBRARY_SYSTEM\step2\article.py", line 154, in is_article_tag_available
    doc = read_json_file(xml_file_path)
  File "E:\NAL-USDA\NAL_LIBRARY_SYSTEM\step2\article.py", line 141, in read_json_file
    shutil.copy(xml_file_path, destination)
  File "C:\Users\prasenjit\AppData\Local\Programs\Python\Python310\lib\shutil.py", line 417, in copy
    copyfile(src, dst, follow_symlinks=follow_symlinks)
  File "C:\Users\prasenjit\AppData\Local\Programs\Python\Python310\lib\shutil.py", line 254, in copyfile
    with open(src, 'rb') as fsrc:
FileNotFoundError: [Errno 2] No such file or directory: 'E:\\NAL-USDA\\NAL_LIBRARY_SYSTEM\\INVALID_XML_FILES\\AN17032_COabs.xml'
ERROR 2024-05-03 21:29:18,119 basehttp 21256 12728 "GET /step2/test-xml/ HTTP/1.1" 500 119785
ERROR 2024-05-03 21:29:59,399 log 21256 30952 Internal Server Error: /step2/test-xml/
Traceback (most recent call last):
  File "E:\NAL-USDA\NAL_LIBRARY_SYSTEM\step2\article.py", line 124, in read_json_file
    with open(file=xml_file_path, mode='rb') as xml_txt:
FileNotFoundError: [Errno 2] No such file or directory: 'E:\\NAL-USDA\\NAL_LIBRARY_SYSTEM\\INVALID_XML_FILES\\AN17032_COabs.xml'

During handling of the above exception, another exception occurred:

Traceback (most recent call last):
  File "e:\NAL-USDA\NAL_LIBRARY_SYSTEM\env\lib\site-packages\django\core\handlers\exception.py", line 55, in inner
    response = get_response(request)
  File "e:\NAL-USDA\NAL_LIBRARY_SYSTEM\env\lib\site-packages\django\core\handlers\base.py", line 197, in _get_response
    response = wrapped_callback(request, *callback_args, **callback_kwargs)
  File "e:\NAL-USDA\NAL_LIBRARY_SYSTEM\env\lib\site-packages\django\views\decorators\csrf.py", line 56, in wrapper_view
    return view_func(*args, **kwargs)
  File "e:\NAL-USDA\NAL_LIBRARY_SYSTEM\env\lib\site-packages\django\views\generic\base.py", line 104, in view
    return self.dispatch(request, *args, **kwargs)
  File "e:\NAL-USDA\NAL_LIBRARY_SYSTEM\env\lib\site-packages\rest_framework\views.py", line 509, in dispatch
    response = self.handle_exception(exc)
  File "e:\NAL-USDA\NAL_LIBRARY_SYSTEM\env\lib\site-packages\rest_framework\views.py", line 469, in handle_exception
    self.raise_uncaught_exception(exc)
  File "e:\NAL-USDA\NAL_LIBRARY_SYSTEM\env\lib\site-packages\rest_framework\views.py", line 480, in raise_uncaught_exception
    raise exc
  File "e:\NAL-USDA\NAL_LIBRARY_SYSTEM\env\lib\site-packages\rest_framework\views.py", line 506, in dispatch
    response = handler(request, *args, **kwargs)
  File "e:\NAL-USDA\NAL_LIBRARY_SYSTEM\env\lib\site-packages\rest_framework\decorators.py", line 50, in handler
    return func(*args, **kwargs)
  File "E:\NAL-USDA\NAL_LIBRARY_SYSTEM\step2\article.py", line 566, in test_xml
    is_article_tag_available(path)
  File "E:\NAL-USDA\NAL_LIBRARY_SYSTEM\step2\article.py", line 154, in is_article_tag_available
    doc = read_json_file(xml_file_path)
  File "E:\NAL-USDA\NAL_LIBRARY_SYSTEM\step2\article.py", line 141, in read_json_file
    shutil.copy(xml_file_path, destination)
  File "C:\Users\prasenjit\AppData\Local\Programs\Python\Python310\lib\shutil.py", line 417, in copy
    copyfile(src, dst, follow_symlinks=follow_symlinks)
  File "C:\Users\prasenjit\AppData\Local\Programs\Python\Python310\lib\shutil.py", line 254, in copyfile
    with open(src, 'rb') as fsrc:
FileNotFoundError: [Errno 2] No such file or directory: 'E:\\NAL-USDA\\NAL_LIBRARY_SYSTEM\\INVALID_XML_FILES\\AN17032_COabs.xml'
ERROR 2024-05-03 21:29:59,407 basehttp 21256 30952 "GET /step2/test-xml/ HTTP/1.1" 500 119785
ERROR 2024-05-03 21:35:25,210 log 7808 28096 Internal Server Error: /step2/test-xml/
Traceback (most recent call last):
  File "E:\NAL-USDA\NAL_LIBRARY_SYSTEM\step2\article.py", line 137, in read_json_file
    return xmltodict.parse(xml_txt, encoding='utf-8')
  File "e:\NAL-USDA\NAL_LIBRARY_SYSTEM\env\lib\site-packages\xmltodict.py", line 378, in parse
    parser.Parse(xml_input, True)
xml.parsers.expat.ExpatError: not well-formed (invalid token): line 30, column 1632

During handling of the above exception, another exception occurred:

Traceback (most recent call last):
  File "e:\NAL-USDA\NAL_LIBRARY_SYSTEM\env\lib\site-packages\django\core\handlers\exception.py", line 55, in inner
    response = get_response(request)
  File "e:\NAL-USDA\NAL_LIBRARY_SYSTEM\env\lib\site-packages\django\core\handlers\base.py", line 197, in _get_response
    response = wrapped_callback(request, *callback_args, **callback_kwargs)
  File "e:\NAL-USDA\NAL_LIBRARY_SYSTEM\env\lib\site-packages\django\views\decorators\csrf.py", line 56, in wrapper_view
    return view_func(*args, **kwargs)
  File "e:\NAL-USDA\NAL_LIBRARY_SYSTEM\env\lib\site-packages\django\views\generic\base.py", line 104, in view
    return self.dispatch(request, *args, **kwargs)
  File "e:\NAL-USDA\NAL_LIBRARY_SYSTEM\env\lib\site-packages\rest_framework\views.py", line 509, in dispatch
    response = self.handle_exception(exc)
  File "e:\NAL-USDA\NAL_LIBRARY_SYSTEM\env\lib\site-packages\rest_framework\views.py", line 469, in handle_exception
    self.raise_uncaught_exception(exc)
  File "e:\NAL-USDA\NAL_LIBRARY_SYSTEM\env\lib\site-packages\rest_framework\views.py", line 480, in raise_uncaught_exception
    raise exc
  File "e:\NAL-USDA\NAL_LIBRARY_SYSTEM\env\lib\site-packages\rest_framework\views.py", line 506, in dispatch
    response = handler(request, *args, **kwargs)
  File "e:\NAL-USDA\NAL_LIBRARY_SYSTEM\env\lib\site-packages\rest_framework\decorators.py", line 50, in handler
    return func(*args, **kwargs)
  File "E:\NAL-USDA\NAL_LIBRARY_SYSTEM\step2\article.py", line 566, in test_xml
    is_article_tag_available(path)
  File "E:\NAL-USDA\NAL_LIBRARY_SYSTEM\step2\article.py", line 154, in is_article_tag_available
    doc = read_json_file(xml_file_path)
  File "E:\NAL-USDA\NAL_LIBRARY_SYSTEM\step2\article.py", line 141, in read_json_file
    shutil.copy(xml_file_path, destination)
  File "C:\Users\prasenjit\AppData\Local\Programs\Python\Python310\lib\shutil.py", line 417, in copy
    copyfile(src, dst, follow_symlinks=follow_symlinks)
  File "C:\Users\prasenjit\AppData\Local\Programs\Python\Python310\lib\shutil.py", line 234, in copyfile
    raise SameFileError("{!r} and {!r} are the same file".format(src, dst))
shutil.SameFileError: 'E:\\NAL-USDA\\NAL_LIBRARY_SYSTEM\\INVALID_XML_FILES\\AN17809_COabs.xml' and 'E:\\NAL-USDA\\NAL_LIBRARY_SYSTEM\\INVALID_XML_FILES\\AN17809_COabs.xml' are the same file
ERROR 2024-05-03 21:35:25,213 basehttp 7808 28096 "GET /step2/test-xml/ HTTP/1.1" 500 142888
ERROR 2024-05-03 21:38:05,775 log 31980 7832 Internal Server Error: /step2/test-xml/
Traceback (most recent call last):
  File "E:\NAL-USDA\NAL_LIBRARY_SYSTEM\step2\article.py", line 137, in read_json_file
    return xmltodict.parse(xml_txt, encoding='utf-8')
  File "e:\NAL-USDA\NAL_LIBRARY_SYSTEM\env\lib\site-packages\xmltodict.py", line 378, in parse
    parser.Parse(xml_input, True)
xml.parsers.expat.ExpatError: no element found: line 18, column 0

During handling of the above exception, another exception occurred:

Traceback (most recent call last):
  File "e:\NAL-USDA\NAL_LIBRARY_SYSTEM\env\lib\site-packages\django\core\handlers\exception.py", line 55, in inner
    response = get_response(request)
  File "e:\NAL-USDA\NAL_LIBRARY_SYSTEM\env\lib\site-packages\django\core\handlers\base.py", line 197, in _get_response
    response = wrapped_callback(request, *callback_args, **callback_kwargs)
  File "e:\NAL-USDA\NAL_LIBRARY_SYSTEM\env\lib\site-packages\django\views\decorators\csrf.py", line 56, in wrapper_view
    return view_func(*args, **kwargs)
  File "e:\NAL-USDA\NAL_LIBRARY_SYSTEM\env\lib\site-packages\django\views\generic\base.py", line 104, in view
    return self.dispatch(request, *args, **kwargs)
  File "e:\NAL-USDA\NAL_LIBRARY_SYSTEM\env\lib\site-packages\rest_framework\views.py", line 509, in dispatch
    response = self.handle_exception(exc)
  File "e:\NAL-USDA\NAL_LIBRARY_SYSTEM\env\lib\site-packages\rest_framework\views.py", line 469, in handle_exception
    self.raise_uncaught_exception(exc)
  File "e:\NAL-USDA\NAL_LIBRARY_SYSTEM\env\lib\site-packages\rest_framework\views.py", line 480, in raise_uncaught_exception
    raise exc
  File "e:\NAL-USDA\NAL_LIBRARY_SYSTEM\env\lib\site-packages\rest_framework\views.py", line 506, in dispatch
    response = handler(request, *args, **kwargs)
  File "e:\NAL-USDA\NAL_LIBRARY_SYSTEM\env\lib\site-packages\rest_framework\decorators.py", line 50, in handler
    return func(*args, **kwargs)
  File "E:\NAL-USDA\NAL_LIBRARY_SYSTEM\step2\article.py", line 566, in test_xml
    is_article_tag_available(path)
  File "E:\NAL-USDA\NAL_LIBRARY_SYSTEM\step2\article.py", line 154, in is_article_tag_available
    doc = read_json_file(xml_file_path)
  File "E:\NAL-USDA\NAL_LIBRARY_SYSTEM\step2\article.py", line 141, in read_json_file
    shutil.copy(xml_file_path, destination)
  File "C:\Users\prasenjit\AppData\Local\Programs\Python\Python310\lib\shutil.py", line 417, in copy
    copyfile(src, dst, follow_symlinks=follow_symlinks)
  File "C:\Users\prasenjit\AppData\Local\Programs\Python\Python310\lib\shutil.py", line 234, in copyfile
    raise SameFileError("{!r} and {!r} are the same file".format(src, dst))
shutil.SameFileError: 'E:\\NAL-USDA\\NAL_LIBRARY_SYSTEM\\INVALID_XML_FILES\\CH08198abs.xml' and 'E:\\NAL-USDA\\NAL_LIBRARY_SYSTEM\\INVALID_XML_FILES\\CH08198abs.xml' are the same file
ERROR 2024-05-03 21:38:05,775 basehttp 31980 7832 "GET /step2/test-xml/ HTTP/1.1" 500 128211
ERROR 2024-05-03 21:39:24,247 log 31980 7832 Internal Server Error: /step2/test-xml/
Traceback (most recent call last):
  File "E:\NAL-USDA\NAL_LIBRARY_SYSTEM\step2\article.py", line 137, in read_json_file
    return xmltodict.parse(xml_txt, encoding='utf-8')
  File "e:\NAL-USDA\NAL_LIBRARY_SYSTEM\env\lib\site-packages\xmltodict.py", line 378, in parse
    parser.Parse(xml_input, True)
xml.parsers.expat.ExpatError: no element found: line 18, column 0

During handling of the above exception, another exception occurred:

Traceback (most recent call last):
  File "e:\NAL-USDA\NAL_LIBRARY_SYSTEM\env\lib\site-packages\django\core\handlers\exception.py", line 55, in inner
    response = get_response(request)
  File "e:\NAL-USDA\NAL_LIBRARY_SYSTEM\env\lib\site-packages\django\core\handlers\base.py", line 197, in _get_response
    response = wrapped_callback(request, *callback_args, **callback_kwargs)
  File "e:\NAL-USDA\NAL_LIBRARY_SYSTEM\env\lib\site-packages\django\views\decorators\csrf.py", line 56, in wrapper_view
    return view_func(*args, **kwargs)
  File "e:\NAL-USDA\NAL_LIBRARY_SYSTEM\env\lib\site-packages\django\views\generic\base.py", line 104, in view
    return self.dispatch(request, *args, **kwargs)
  File "e:\NAL-USDA\NAL_LIBRARY_SYSTEM\env\lib\site-packages\rest_framework\views.py", line 509, in dispatch
    response = self.handle_exception(exc)
  File "e:\NAL-USDA\NAL_LIBRARY_SYSTEM\env\lib\site-packages\rest_framework\views.py", line 469, in handle_exception
    self.raise_uncaught_exception(exc)
  File "e:\NAL-USDA\NAL_LIBRARY_SYSTEM\env\lib\site-packages\rest_framework\views.py", line 480, in raise_uncaught_exception
    raise exc
  File "e:\NAL-USDA\NAL_LIBRARY_SYSTEM\env\lib\site-packages\rest_framework\views.py", line 506, in dispatch
    response = handler(request, *args, **kwargs)
  File "e:\NAL-USDA\NAL_LIBRARY_SYSTEM\env\lib\site-packages\rest_framework\decorators.py", line 50, in handler
    return func(*args, **kwargs)
  File "E:\NAL-USDA\NAL_LIBRARY_SYSTEM\step2\article.py", line 566, in test_xml
    is_article_tag_available(path)
  File "E:\NAL-USDA\NAL_LIBRARY_SYSTEM\step2\article.py", line 154, in is_article_tag_available
    doc = read_json_file(xml_file_path)
  File "E:\NAL-USDA\NAL_LIBRARY_SYSTEM\step2\article.py", line 141, in read_json_file
    shutil.copy(xml_file_path, destination)
  File "C:\Users\prasenjit\AppData\Local\Programs\Python\Python310\lib\shutil.py", line 417, in copy
    copyfile(src, dst, follow_symlinks=follow_symlinks)
  File "C:\Users\prasenjit\AppData\Local\Programs\Python\Python310\lib\shutil.py", line 234, in copyfile
    raise SameFileError("{!r} and {!r} are the same file".format(src, dst))
shutil.SameFileError: 'E:\\NAL-USDA\\NAL_LIBRARY_SYSTEM\\INVALID_XML_FILES\\CH08198abs.xml' and 'E:\\NAL-USDA\\NAL_LIBRARY_SYSTEM\\INVALID_XML_FILES\\CH08198abs.xml' are the same file
ERROR 2024-05-03 21:39:24,263 basehttp 31980 7832 "GET /step2/test-xml/ HTTP/1.1" 500 128599
ERROR 2024-05-03 22:03:16,786 log 19880 25776 Internal Server Error: /step2/test-xml/
Traceback (most recent call last):
  File "E:\NAL-USDA\NAL_LIBRARY_SYSTEM\step2\article.py", line 137, in read_json_file
    return xmltodict.parse(xml_txt, encoding='utf-8')
  File "e:\NAL-USDA\NAL_LIBRARY_SYSTEM\env\lib\site-packages\xmltodict.py", line 378, in parse
    parser.Parse(xml_input, True)
xml.parsers.expat.ExpatError: not well-formed (invalid token): line 35, column 664

During handling of the above exception, another exception occurred:

Traceback (most recent call last):
  File "e:\NAL-USDA\NAL_LIBRARY_SYSTEM\env\lib\site-packages\django\core\handlers\exception.py", line 55, in inner
    response = get_response(request)
  File "e:\NAL-USDA\NAL_LIBRARY_SYSTEM\env\lib\site-packages\django\core\handlers\base.py", line 197, in _get_response
    response = wrapped_callback(request, *callback_args, **callback_kwargs)
  File "e:\NAL-USDA\NAL_LIBRARY_SYSTEM\env\lib\site-packages\django\views\decorators\csrf.py", line 56, in wrapper_view
    return view_func(*args, **kwargs)
  File "e:\NAL-USDA\NAL_LIBRARY_SYSTEM\env\lib\site-packages\django\views\generic\base.py", line 104, in view
    return self.dispatch(request, *args, **kwargs)
  File "e:\NAL-USDA\NAL_LIBRARY_SYSTEM\env\lib\site-packages\rest_framework\views.py", line 509, in dispatch
    response = self.handle_exception(exc)
  File "e:\NAL-USDA\NAL_LIBRARY_SYSTEM\env\lib\site-packages\rest_framework\views.py", line 469, in handle_exception
    self.raise_uncaught_exception(exc)
  File "e:\NAL-USDA\NAL_LIBRARY_SYSTEM\env\lib\site-packages\rest_framework\views.py", line 480, in raise_uncaught_exception
    raise exc
  File "e:\NAL-USDA\NAL_LIBRARY_SYSTEM\env\lib\site-packages\rest_framework\views.py", line 506, in dispatch
    response = handler(request, *args, **kwargs)
  File "e:\NAL-USDA\NAL_LIBRARY_SYSTEM\env\lib\site-packages\rest_framework\decorators.py", line 50, in handler
    return func(*args, **kwargs)
  File "E:\NAL-USDA\NAL_LIBRARY_SYSTEM\step2\article.py", line 566, in test_xml
    is_article_tag_available(path)
  File "E:\NAL-USDA\NAL_LIBRARY_SYSTEM\step2\article.py", line 154, in is_article_tag_available
    doc = read_json_file(xml_file_path)
  File "E:\NAL-USDA\NAL_LIBRARY_SYSTEM\step2\article.py", line 141, in read_json_file
    shutil.copy(xml_file_path, destination)
  File "C:\Users\prasenjit\AppData\Local\Programs\Python\Python310\lib\shutil.py", line 417, in copy
    copyfile(src, dst, follow_symlinks=follow_symlinks)
  File "C:\Users\prasenjit\AppData\Local\Programs\Python\Python310\lib\shutil.py", line 234, in copyfile
    raise SameFileError("{!r} and {!r} are the same file".format(src, dst))
shutil.SameFileError: 'E:\\NAL-USDA\\NAL_LIBRARY_SYSTEM\\INVALID_XML_FILES\\AN18724_COabs.xml' and 'E:\\NAL-USDA\\NAL_LIBRARY_SYSTEM\\INVALID_XML_FILES\\AN18724_COabs.xml' are the same file
ERROR 2024-05-03 22:03:16,806 basehttp 19880 25776 "GET /step2/test-xml/ HTTP/1.1" 500 143138
ERROR 2024-05-07 11:06:40,186 log 36988 11168 Internal Server Error: /step1/download-from-crossref-api/
Traceback (most recent call last):
  File "e:\NAL-USDA\NAL_LIBRARY_SYSTEM\env\lib\site-packages\django\core\handlers\exception.py", line 55, in inner
    response = get_response(request)
  File "e:\NAL-USDA\NAL_LIBRARY_SYSTEM\env\lib\site-packages\django\core\handlers\base.py", line 197, in _get_response
    response = wrapped_callback(request, *callback_args, **callback_kwargs)
  File "e:\NAL-USDA\NAL_LIBRARY_SYSTEM\env\lib\site-packages\django\views\decorators\csrf.py", line 56, in wrapper_view
    return view_func(*args, **kwargs)
  File "e:\NAL-USDA\NAL_LIBRARY_SYSTEM\env\lib\site-packages\django\views\generic\base.py", line 104, in view
    return self.dispatch(request, *args, **kwargs)
  File "e:\NAL-USDA\NAL_LIBRARY_SYSTEM\env\lib\site-packages\rest_framework\views.py", line 509, in dispatch
    response = self.handle_exception(exc)
  File "e:\NAL-USDA\NAL_LIBRARY_SYSTEM\env\lib\site-packages\rest_framework\views.py", line 469, in handle_exception
    self.raise_uncaught_exception(exc)
  File "e:\NAL-USDA\NAL_LIBRARY_SYSTEM\env\lib\site-packages\rest_framework\views.py", line 480, in raise_uncaught_exception
    raise exc
  File "e:\NAL-USDA\NAL_LIBRARY_SYSTEM\env\lib\site-packages\rest_framework\views.py", line 506, in dispatch
    response = handler(request, *args, **kwargs)
  File "e:\NAL-USDA\NAL_LIBRARY_SYSTEM\env\lib\site-packages\rest_framework\decorators.py", line 50, in handler
    return func(*args, **kwargs)
  File "E:\NAL-USDA\NAL_LIBRARY_SYSTEM\step1\crossref_api.py", line 165, in download_from_crossref_api
    'Crossref-Plus-API-Token': 'Bearer {}'.format(api.pswd),
UnboundLocalError: local variable 'api' referenced before assignment
ERROR 2024-05-07 11:06:40,205 basehttp 36988 11168 "GET /step1/download-from-crossref-api/ HTTP/1.1" 500 100467
ERROR 2024-05-07 22:28:30,545 log 32968 36912 Internal Server Error: /providers-api/
Traceback (most recent call last):
  File "e:\NAL-USDA\NAL_LIBRARY_SYSTEM\env\lib\site-packages\cryptography\fernet.py", line 130, in _verify_signature
    h.verify(data[-32:])
cryptography.exceptions.InvalidSignature: Signature did not match digest.

During handling of the above exception, another exception occurred:

Traceback (most recent call last):
  File "e:\NAL-USDA\NAL_LIBRARY_SYSTEM\env\lib\site-packages\django\core\handlers\exception.py", line 55, in inner
    response = get_response(request)
  File "e:\NAL-USDA\NAL_LIBRARY_SYSTEM\env\lib\site-packages\django\core\handlers\base.py", line 197, in _get_response
    response = wrapped_callback(request, *callback_args, **callback_kwargs)
  File "e:\NAL-USDA\NAL_LIBRARY_SYSTEM\env\lib\site-packages\django\views\decorators\csrf.py", line 56, in wrapper_view
    return view_func(*args, **kwargs)
  File "e:\NAL-USDA\NAL_LIBRARY_SYSTEM\env\lib\site-packages\rest_framework\viewsets.py", line 125, in view
    return self.dispatch(request, *args, **kwargs)
  File "e:\NAL-USDA\NAL_LIBRARY_SYSTEM\env\lib\site-packages\rest_framework\views.py", line 509, in dispatch
    response = self.handle_exception(exc)
  File "e:\NAL-USDA\NAL_LIBRARY_SYSTEM\env\lib\site-packages\rest_framework\views.py", line 469, in handle_exception
    self.raise_uncaught_exception(exc)
  File "e:\NAL-USDA\NAL_LIBRARY_SYSTEM\env\lib\site-packages\rest_framework\views.py", line 480, in raise_uncaught_exception
    raise exc
  File "e:\NAL-USDA\NAL_LIBRARY_SYSTEM\env\lib\site-packages\rest_framework\views.py", line 506, in dispatch
    response = handler(request, *args, **kwargs)
  File "e:\NAL-USDA\NAL_LIBRARY_SYSTEM\env\lib\site-packages\rest_framework\mixins.py", line 46, in list
    return Response(serializer.data)
  File "e:\NAL-USDA\NAL_LIBRARY_SYSTEM\env\lib\site-packages\rest_framework\serializers.py", line 768, in data
    ret = super().data
  File "e:\NAL-USDA\NAL_LIBRARY_SYSTEM\env\lib\site-packages\rest_framework\serializers.py", line 253, in data
    self._data = self.to_representation(self.instance)
  File "e:\NAL-USDA\NAL_LIBRARY_SYSTEM\env\lib\site-packages\rest_framework\serializers.py", line 686, in to_representation
    return [
  File "e:\NAL-USDA\NAL_LIBRARY_SYSTEM\env\lib\site-packages\django\db\models\query.py", line 398, in __iter__
    self._fetch_all()
  File "e:\NAL-USDA\NAL_LIBRARY_SYSTEM\env\lib\site-packages\django\db\models\query.py", line 1881, in _fetch_all
    self._result_cache = list(self._iterable_class(self))
  File "e:\NAL-USDA\NAL_LIBRARY_SYSTEM\env\lib\site-packages\django\db\models\query.py", line 121, in __iter__
    for row in compiler.results_iter(results):
  File "e:\NAL-USDA\NAL_LIBRARY_SYSTEM\env\lib\site-packages\django\db\models\sql\compiler.py", line 1498, in apply_converters
    value = converter(value, expression, connection)
  File "E:\NAL-USDA\NAL_LIBRARY_SYSTEM\configurations\common.py", line 132, in from_db_value
    return self.cipher_suite.decrypt(value.encode()).decode()
  File "e:\NAL-USDA\NAL_LIBRARY_SYSTEM\env\lib\site-packages\cryptography\fernet.py", line 89, in decrypt
    return self._decrypt_data(data, timestamp, time_info)
  File "e:\NAL-USDA\NAL_LIBRARY_SYSTEM\env\lib\site-packages\cryptography\fernet.py", line 148, in _decrypt_data
    self._verify_signature(data)
  File "e:\NAL-USDA\NAL_LIBRARY_SYSTEM\env\lib\site-packages\cryptography\fernet.py", line 132, in _verify_signature
    raise InvalidToken
cryptography.fernet.InvalidToken
ERROR 2024-05-07 22:28:30,545 basehttp 32968 36912 "GET /providers-api/ HTTP/1.1" 500 161127
ERROR 2024-05-07 22:28:40,034 log 32968 36912 Internal Server Error: /providers-api/
Traceback (most recent call last):
  File "e:\NAL-USDA\NAL_LIBRARY_SYSTEM\env\lib\site-packages\cryptography\fernet.py", line 130, in _verify_signature
    h.verify(data[-32:])
cryptography.exceptions.InvalidSignature: Signature did not match digest.

During handling of the above exception, another exception occurred:

Traceback (most recent call last):
  File "e:\NAL-USDA\NAL_LIBRARY_SYSTEM\env\lib\site-packages\django\core\handlers\exception.py", line 55, in inner
    response = get_response(request)
  File "e:\NAL-USDA\NAL_LIBRARY_SYSTEM\env\lib\site-packages\django\core\handlers\base.py", line 197, in _get_response
    response = wrapped_callback(request, *callback_args, **callback_kwargs)
  File "e:\NAL-USDA\NAL_LIBRARY_SYSTEM\env\lib\site-packages\django\views\decorators\csrf.py", line 56, in wrapper_view
    return view_func(*args, **kwargs)
  File "e:\NAL-USDA\NAL_LIBRARY_SYSTEM\env\lib\site-packages\rest_framework\viewsets.py", line 125, in view
    return self.dispatch(request, *args, **kwargs)
  File "e:\NAL-USDA\NAL_LIBRARY_SYSTEM\env\lib\site-packages\rest_framework\views.py", line 509, in dispatch
    response = self.handle_exception(exc)
  File "e:\NAL-USDA\NAL_LIBRARY_SYSTEM\env\lib\site-packages\rest_framework\views.py", line 469, in handle_exception
    self.raise_uncaught_exception(exc)
  File "e:\NAL-USDA\NAL_LIBRARY_SYSTEM\env\lib\site-packages\rest_framework\views.py", line 480, in raise_uncaught_exception
    raise exc
  File "e:\NAL-USDA\NAL_LIBRARY_SYSTEM\env\lib\site-packages\rest_framework\views.py", line 506, in dispatch
    response = handler(request, *args, **kwargs)
  File "e:\NAL-USDA\NAL_LIBRARY_SYSTEM\env\lib\site-packages\rest_framework\mixins.py", line 46, in list
    return Response(serializer.data)
  File "e:\NAL-USDA\NAL_LIBRARY_SYSTEM\env\lib\site-packages\rest_framework\serializers.py", line 768, in data
    ret = super().data
  File "e:\NAL-USDA\NAL_LIBRARY_SYSTEM\env\lib\site-packages\rest_framework\serializers.py", line 253, in data
    self._data = self.to_representation(self.instance)
  File "e:\NAL-USDA\NAL_LIBRARY_SYSTEM\env\lib\site-packages\rest_framework\serializers.py", line 686, in to_representation
    return [
  File "e:\NAL-USDA\NAL_LIBRARY_SYSTEM\env\lib\site-packages\django\db\models\query.py", line 398, in __iter__
    self._fetch_all()
  File "e:\NAL-USDA\NAL_LIBRARY_SYSTEM\env\lib\site-packages\django\db\models\query.py", line 1881, in _fetch_all
    self._result_cache = list(self._iterable_class(self))
  File "e:\NAL-USDA\NAL_LIBRARY_SYSTEM\env\lib\site-packages\django\db\models\query.py", line 121, in __iter__
    for row in compiler.results_iter(results):
  File "e:\NAL-USDA\NAL_LIBRARY_SYSTEM\env\lib\site-packages\django\db\models\sql\compiler.py", line 1498, in apply_converters
    value = converter(value, expression, connection)
  File "E:\NAL-USDA\NAL_LIBRARY_SYSTEM\configurations\common.py", line 132, in from_db_value
    return self.cipher_suite.decrypt(value.encode()).decode()
  File "e:\NAL-USDA\NAL_LIBRARY_SYSTEM\env\lib\site-packages\cryptography\fernet.py", line 89, in decrypt
    return self._decrypt_data(data, timestamp, time_info)
  File "e:\NAL-USDA\NAL_LIBRARY_SYSTEM\env\lib\site-packages\cryptography\fernet.py", line 148, in _decrypt_data
    self._verify_signature(data)
  File "e:\NAL-USDA\NAL_LIBRARY_SYSTEM\env\lib\site-packages\cryptography\fernet.py", line 132, in _verify_signature
    raise InvalidToken
cryptography.fernet.InvalidToken
ERROR 2024-05-07 22:28:40,034 basehttp 32968 36912 "GET /providers-api/ HTTP/1.1" 500 160976
ERROR 2024-05-08 14:38:55,324 log 11508 16244 Internal Server Error: /step1/download-from-chorus-api/
Traceback (most recent call last):
  File "e:\NAL-USDA\NAL_LIBRARY_SYSTEM\env\lib\site-packages\django\core\handlers\exception.py", line 55, in inner
    response = get_response(request)
  File "e:\NAL-USDA\NAL_LIBRARY_SYSTEM\env\lib\site-packages\django\core\handlers\base.py", line 197, in _get_response
    response = wrapped_callback(request, *callback_args, **callback_kwargs)
  File "e:\NAL-USDA\NAL_LIBRARY_SYSTEM\env\lib\site-packages\django\views\decorators\csrf.py", line 56, in wrapper_view
    return view_func(*args, **kwargs)
  File "e:\NAL-USDA\NAL_LIBRARY_SYSTEM\env\lib\site-packages\django\views\generic\base.py", line 104, in view
    return self.dispatch(request, *args, **kwargs)
  File "e:\NAL-USDA\NAL_LIBRARY_SYSTEM\env\lib\site-packages\rest_framework\views.py", line 509, in dispatch
    response = self.handle_exception(exc)
  File "e:\NAL-USDA\NAL_LIBRARY_SYSTEM\env\lib\site-packages\rest_framework\views.py", line 469, in handle_exception
    self.raise_uncaught_exception(exc)
  File "e:\NAL-USDA\NAL_LIBRARY_SYSTEM\env\lib\site-packages\rest_framework\views.py", line 480, in raise_uncaught_exception
    raise exc
  File "e:\NAL-USDA\NAL_LIBRARY_SYSTEM\env\lib\site-packages\rest_framework\views.py", line 506, in dispatch
    response = handler(request, *args, **kwargs)
  File "e:\NAL-USDA\NAL_LIBRARY_SYSTEM\env\lib\site-packages\rest_framework\decorators.py", line 50, in handler
    return func(*args, **kwargs)
  File "E:\NAL-USDA\NAL_LIBRARY_SYSTEM\step1\chorus_api.py", line 182, in download_from_chorus_api
    save_files(publisher, api)
  File "E:\NAL-USDA\NAL_LIBRARY_SYSTEM\step1\chorus_api.py", line 102, in save_files
    f = open(fname, 'r')
FileNotFoundError: [Errno 2] No such file or directory: 'E:\\NAL-USDA\\NAL_LIBRARY_SYSTEM\\ARCHIVE_ARTICLE\\CHORUS\\12\\10.1175_jtech-d-16-0130.1.json'
ERROR 2024-05-08 14:38:55,328 basehttp 11508 16244 "GET /step1/download-from-chorus-api/ HTTP/1.1" 500 132438
